File: MaterialsTesting/Specimen_RawData_3.csv
Time,Extension,Load
(s),(mm),(N)
"0.00000","0.00000","0.10515"
"0.20000","0.00609","0.22517"
"0.40000","0.01445","-0.26169"
"0.60000","0.02277","0.16071"
"0.80000","0.03110","0.09542"
"1.00000","0.03943","0.05521"
"1.20000","0.04774","-0.23094"
"1.40000","0.05608","0.03187"
"1.60000","0.06445","-0.12347"
"1.80000","0.07279","0.06080"
"2.00000","0.08111","-0.18951"
"2.20000","0.08944","0.02035"
"2.40000","0.09776","-0.35923"
"2.60000","0.10612","-0.09077"
"2.80000","0.11446","-0.09936"
"3.00000","0.12276","-0.18504"
"3.20000","0.13108","0.05240"
"3.40000","0.13945","-0.08145"
"3.60000","0.14779","-0.04717"
"3.80000","0.15610","0.23671"
"4.00000","0.16441","0.10203"
"4.20000","0.17278","-0.07499"
"4.40000","0.18115","0.11402"
"4.60000","0.18943","-0.02074"
"4.80000","0.19771","-0.32282"
"5.00000","0.20609","0.19563"
"5.20000","0.21443","-0.07812"
"5.40000","0.22277","0.07469"
"5.60000","0.23112","-0.05937"
"5.80000","0.23943","0.17260"
"6.00000","0.24776","0.30412"
"6.20000","0.25613","0.27614"
"6.40000","0.26445","0.09935"
"6.60000","0.27277","-0.07947"
"6.80000","0.28108","-0.11694"
"7.00000","0.28939","0.10423"
"7.20000","0.29776","0.37197"
"7.40000","0.30615","0.33106"
"7.60000","0.31445","0.03147"
"7.80000","0.32276","0.40246"
"8.00000","0.33110","0.19520"
"8.20000","0.33945","-0.07647"
"8.40000","0.34778","0.13511"
"8.60000","0.35608","-0.19075"
"8.80000","0.36440","-0.01441"
"9.00000","0.37277","0.06091"
"9.20000","0.38111","0.18730"
"9.40000","0.38944","0.17634"
"9.60000","0.39778","-0.04127"
"9.80000","0.40609","0.11442"
"10.00000","0.41443","0.03132"
"10.20000","0.42278","-0.18702"
"10.40000","0.43110","0.04886"
"10.60000","0.43944","0.23447"
"10.80000","0.44777","0.04237"
"11.00000","0.45610","0.11578"
"11.20000","0.46445","0.05604"
"11.40000","0.47279","0.02184"
"11.60000","0.48106","-0.23691"
"11.80000","0.48939","0.04644"
"12.00000","0.49778","-0.02337"
"12.20000","0.50614","0.12873"
"12.40000","0.51445","0.09911"
"12.60000","0.52275","0.20674"
"12.80000","0.53109","0.01842"
"13.00000","0.53946","-0.09820"
"13.20000","0.54777","0.21170"
"13.40000","0.55606","-0.00350"
"13.60000","0.56440","0.00786"
"13.80000","0.57277","-0.09276"
"14.00000","0.58113","0.02851"
"14.20000","0.58947","-0.14318"
"14.40000","0.59778","-0.12381"
"14.60000","0.60610","-0.06319"
"14.80000","0.61443","-0.19920"
"15.00000","0.62276","0.07968"
"15.20000","0.63108","-0.02353"
"15.40000","0.63941","0.11073"
"15.60000","0.64775","0.07224"
"15.80000","0.65613","0.28811"
"16.00000","0.66450","0.09278"
"16.20000","0.67281","0.14828"
"16.40000","0.68110","0.01719"
"16.60000","0.68942","0.04426"
"16.80000","0.69776","-0.15129"
"17.00000","0.70609","0.04825"
"17.20000","0.71442","0.19809"
"17.40000","0.72274","0.01482"
"17.60000","0.73111","0.29305"
"17.80000","0.73948","0.15457"
"18.00000","0.74780","0.04954"
"18.20000","0.75611","0.23585"
"18.40000","0.76442","0.17912"
"18.60000","0.77273","0.03387"
"18.80000","0.78109","0.08966"
"19.00000","0.78943","-0.00558"
"19.20000","0.79776","-0.25823"
"19.40000","0.80611","0.02858"
"19.60000","0.81445","0.27777"
"19.80000","0.82279","0.01453"
"20.00000","0.83115","0.06535"
"20.20000","0.83943","0.22822"
"20.40000","0.84773","-0.08187"
"20.60000","0.85609","0.04003"
"20.80000","0.86444","-0.12883"
"21.00000","0.87277","0.15439"
"21.20000","0.88110","-0.03572"
"21.40000","0.88944","-0.22928"
"21.60000","0.89782","-0.04188"
"21.80000","0.90613","-0.05444"
"22.00000","0.91440","-0.13102"
"22.20000","0.92272","0.14776"
"22.40000","0.93108","0.07159"
"22.60000","0.93943","0.05654"
"22.80000","0.94779","-0.08984"
"23.00000","0.95610","0.17297"
"23.20000","0.96444","0.20294"
"23.40000","0.97279","-0.01795"
"23.60000","0.98113","0.29616"
"23.80000","0.98944","0.40026"
"24.00000","0.99776","0.13343"
"24.20000","1.00606","0.02763"
"24.40000","1.01443","0.12915"
"24.60000","1.02280","0.33036"
"24.80000","1.03112","-0.16559"
"25.00000","1.03944","0.00781"
"25.20000","1.04776","0.17840"
"25.40000","1.05613","0.13656"
"25.60000","1.06446","0.21420"
"25.80000","1.07274","0.02453"
"26.00000","1.08106","0.16828"
"26.20000","1.08943","0.11895"
"26.40000","1.09778","-0.12959"
"26.60000","1.10613","-0.32438"
"26.80000","1.11444","-0.31206"
"27.00000","1.12277","0.16601"
"27.20000","1.13111","0.39641"
"27.40000","1.13944","-0.08214"
"27.60000","1.14776","0.10128"
"27.80000","1.15609","0.11701"
"28.00000","1.16443","0.18162"
"28.20000","1.17278","0.07582"
"28.40000","1.18112","0.49286"
"28.60000","1.18947","0.10782"
"28.80000","1.19776","0.27699"
"29.00000","1.20607","0.30178"
"29.20000","1.21444","0.29599"
"29.40000","1.22278","0.22994"
"29.60000","1.23112","0.12053"
"29.80000","1.23942","0.34253"
"30.00000","1.24775","-0.16786"
"30.20000","1.25613","0.23547"
"30.40000","1.26446","0.21180"
"30.60000","1.27275","0.25994"
"30.80000","1.28108","0.01068"
"31.00000","1.28942","-0.05186"
"31.20000","1.29779","0.04679"
"31.40000","1.30613","0.18306"
"31.60000","1.31444","0.23635"
"31.80000","1.32276","0.11957"
"32.00000","1.33111","0.20743"
"32.20000","1.33944","0.41414"
"32.40000","1.34778","0.24741"
"32.60000","1.35608","0.10924"
"32.80000","1.36440","0.05061"
"33.00000","1.37277","0.26707"
"33.20000","1.38115","-0.01323"
"33.40000","1.38946","0.04039"
"33.60000","1.39777","0.16469"
"33.80000","1.40609","0.07043"
"34.00000","1.41444","0.02509"
"34.20000","1.42278","0.24380"
"34.40000","1.43107","0.08714"
"34.60000","1.43939","-0.07674"
"34.80000","1.44777","0.21145"
"35.00000","1.45613","0.18395"
"35.20000","1.46447","0.11080"
"35.40000","1.47278","0.25883"
"35.60000","1.48109","0.17426"
"35.80000","1.48942","0.27105"
"36.00000","1.49776","0.11039"
"36.20000","1.50609","0.19182"
"36.40000","1.51442","0.00125"
"36.60000","1.52277","0.16641"
"36.80000","1.53111","0.10838"
"37.00000","1.53945","0.02529"
"37.20000","1.54781","0.20712"
"37.40000","1.55611","0.21834"
"37.60000","1.56440","0.20234"
"37.80000","1.57274","0.09802"
"38.00000","1.58109","0.13419"
"38.20000","1.58944","0.07974"
"38.40000","1.59775","0.08242"
"38.60000","1.60610","0.35757"
"38.80000","1.61449","0.18817"
"39.00000","1.62279","0.20488"
"39.20000","1.63109","-0.08625"
"39.40000","1.63942","0.33546"
"39.60000","1.64773","0.04776"
"39.80000","1.65610","0.15706"
"40.00000","1.66444","-0.02016"
"40.20000","1.67276","0.21613"
"40.40000","1.68111","0.01198"
"40.60000","1.68948","0.31835"
"40.80000","1.69780","0.17301"
"41.00000","1.70611","0.03521"
"41.20000","1.71441","0.54185"
"41.40000","1.72271","0.09559"
"41.60000","1.73107","0.16003"
"41.80000","1.73946","0.38756"
"42.00000","1.74779","0.36555"
"42.20000","1.75612","0.26937"
"42.40000","1.76444","0.32366"
"42.60000","1.77279","0.18773"
"42.80000","1.78111","0.30331"
"43.00000","1.78940","0.26201"
"43.20000","1.79772","0.56269"
"43.40000","1.80608","0.77321"
"43.60000","1.81444","0.80179"
"43.80000","1.82282","1.05253"
"44.00000","1.83112","1.02936"
"44.20000","1.83945","1.29235"
"44.40000","1.84779","1.60653"
"44.60000","1.85612","2.03308"
"44.80000","1.86441","2.12133"
"45.00000","1.87273","2.03682"
"45.20000","1.88109","2.20783"
"45.40000","1.88945","2.30583"
"45.60000","1.89779","2.45214"
"45.80000","1.90615","2.38233"
"46.00000","1.91444","2.69379"
"46.20000","1.92275","2.68281"
"46.40000","1.93110","2.68176"
"46.60000","1.93944","2.56634"
"46.80000","1.94776","3.13153"
"47.00000","1.95608","3.58835"
"47.20000","1.96441","4.74812"
"47.40000","1.97278","5.80085"
"47.60000","1.98114","7.03943"
"47.80000","1.98944","7.69229"
"48.00000","1.99775","8.42113"
"48.20000","2.00609","9.73962"
"48.40000","2.01444","11.02064"
"48.60000","2.02277","12.69447"
"48.80000","2.03109","13.92172"
"49.00000","2.03942","15.39901"
"49.20000","2.04778","16.84756"
"49.40000","2.05611","17.61351"
"49.60000","2.06446","18.64560"
"49.80000","2.07275","19.59057"
"50.00000","2.08108","20.75835"
"50.20000","2.08943","21.93167"
"50.40000","2.09780","22.95603"
"50.60000","2.10612","24.66059"
"50.80000","2.11445","25.71930"
"51.00000","2.12276","27.54558"
"51.20000","2.13112","28.98961"
"51.40000","2.13946","30.57237"
"51.60000","2.14776","32.74055"
"51.80000","2.15605","34.20700"
"52.00000","2.16440","36.09329"
"52.20000","2.17279","38.14487"
"52.40000","2.18114","40.25327"
"52.60000","2.18945","42.14776"
"52.80000","2.19775","44.37318"
"53.00000","2.20610","46.49053"
"53.20000","2.21445","47.96879"
"53.40000","2.22276","50.15297"
"53.60000","2.23107","52.48817"
"53.80000","2.23944","55.23713"
"54.00000","2.24778","58.14734"
"54.20000","2.25611","61.53900"
"54.40000","2.26446","64.86273"
"54.60000","2.27278","68.68573"
"54.80000","2.28108","72.28200"
"55.00000","2.28943","75.97961"
"55.20000","2.29775","80.30052"
"55.40000","2.30610","84.23185"
"55.60000","2.31442","88.66582"
"55.80000","2.32276","92.39255"
"56.00000","2.33114","97.11312"
"56.20000","2.33947","101.65926"
"56.40000","2.34778","106.31224"
"56.60000","2.35609","110.78551"
"56.80000","2.36440","114.97351"
"57.00000","2.37275","119.95091"
"57.20000","2.38111","124.63970"
"57.40000","2.38942","129.61713"
"57.60000","2.39777","134.39865"
"57.80000","2.40613","139.41560"
"58.00000","2.41447","145.13504"
"58.20000","2.42278","150.68124"
"58.40000","2.43109","155.96432"
"58.60000","2.43941","161.55133"
"58.80000","2.44773","167.25821"
"59.00000","2.45611","173.40250"
"59.20000","2.46445","179.44540"
"59.40000","2.47278","185.68478"
"59.60000","2.48110","191.82584"
"59.80000","2.48946","198.07603"
"60.00000","2.49779","204.40536"
"60.20000","2.50610","211.08571"
"60.40000","2.51440","218.17012"
"60.60000","2.52272","224.94041"
"60.80000","2.53109","231.93250"
"61.00000","2.53946","238.80167"
"61.20000","2.54778","245.96208"
"61.40000","2.55610","253.16312"
"61.60000","2.56446","260.53030"
"61.80000","2.57282","267.64212"
"62.00000","2.58109","275.32278"
"62.20000","2.58939","282.87299"
"62.40000","2.59773","290.55402"
"62.60000","2.60609","298.84949"
"62.80000","2.61444","306.80258"
"63.00000","2.62281","314.50809"
"63.20000","2.63111","322.73959"
"63.40000","2.63944","331.22424"
"63.60000","2.64779","339.38382"
"63.80000","2.65610","347.35873"
"64.00000","2.66442","356.29456"
"64.20000","2.67274","364.53549"
"64.40000","2.68106","372.81747"
"64.60000","2.68943","381.25739"
"64.80000","2.69780","390.02292"
"65.00000","2.70611","398.38184"
"65.20000","2.71443","407.20074"
"65.40000","2.72276","415.49155"
"65.60000","2.73112","423.85568"
"65.80000","2.73944","432.15073"
"66.00000","2.74774","440.62650"
"66.20000","2.75608","449.25217"
"66.40000","2.76445","457.47296"
"66.60000","2.77278","465.77753"
"66.80000","2.78111","474.27655"
"67.00000","2.78944","482.57193"
"67.20000","2.79775","490.84940"
"67.40000","2.80609","499.22986"
"67.60000","2.81445","507.12521"
"67.80000","2.82277","515.14185"
"68.00000","2.83110","523.08813"
"68.20000","2.83943","530.92639"
"68.40000","2.84779","538.98492"
"68.60000","2.85614","546.72467"
"68.80000","2.86445","554.39557"
"69.00000","2.87272","561.87018"
"69.20000","2.88105","569.60095"
"69.40000","2.88944","577.37128"
"69.60000","2.89781","584.43488"
"69.80000","2.90612","592.01624"
"70.00000","2.91441","599.36700"
"70.20000","2.92276","606.53778"
"70.40000","2.93113","613.99054"
"70.60000","2.93944","620.70990"
"70.80000","2.94772","627.83618"
"71.00000","2.95607","634.52515"
"71.20000","2.96443","641.85535"
"71.40000","2.97278","648.81451"
"71.60000","2.98114","655.53796"
"71.80000","2.98946","662.40527"
"72.00000","2.99776","668.68372"
"72.20000","3.00610","675.31177"
"72.40000","3.01441","682.06000"
"72.60000","3.02275","688.54272"
"72.80000","3.03108","694.96844"
"73.00000","3.03942","701.52844"
"73.20000","3.04780","708.25714"
"73.40000","3.05616","714.54779"
"73.60000","3.06446","720.93079"
"73.80000","3.07277","726.90222"
"74.00000","3.08109","733.11688"
"74.20000","3.08942","739.49323"
"74.40000","3.09775","745.74469"
"74.60000","3.10607","751.86047"
"74.80000","3.11441","757.94531"
"75.00000","3.12281","763.98920"
"75.20000","3.13115","770.23529"
"75.40000","3.13947","775.93207"
"75.60000","3.14777","781.82208"
"75.80000","3.15609","787.74237"
"76.00000","3.16440","793.60077"
"76.20000","3.17275","799.34473"
"76.40000","3.18109","805.18781"
"76.60000","3.18943","811.21112"
"76.80000","3.19778","816.87195"
"77.00000","3.20613","822.59021"
"77.20000","3.21447","828.08240"
"77.40000","3.22280","833.81042"
"77.60000","3.23108","839.28888"
"77.80000","3.23938","845.06714"
"78.00000","3.24775","850.32611"
"78.20000","3.25611","855.95178"
"78.40000","3.26443","861.21393"
"78.60000","3.27276","866.68683"
"78.80000","3.28112","871.88879"
"79.00000","3.28949","877.45001"
"79.20000","3.29779","882.67322"
"79.40000","3.30608","888.06354"
"79.60000","3.31440","893.44391"
"79.80000","3.32275","898.73792"
"80.00000","3.33110","903.97015"
"80.20000","3.33946","909.21753"
"80.40000","3.34778","914.52167"
"80.60000","3.35611","919.50708"
"80.80000","3.36448","925.00439"
"81.00000","3.37278","930.36609"
"81.20000","3.38109","935.39264"
"81.40000","3.38942","940.49011"
"81.60000","3.39773","945.53735"
"81.80000","3.40608","950.43317"
"82.00000","3.41446","955.68585"
"82.20000","3.42280","961.14215"
"82.40000","3.43111","965.93896"
"82.60000","3.43944","970.54120"
"82.80000","3.44779","975.90302"
"83.00000","3.45611","980.87634"
"83.20000","3.46441","985.85938"
"83.40000","3.47273","991.01971"
"83.60000","3.48110","995.80273"
"83.80000","3.48945","1000.79407"
"84.00000","3.49778","1005.49054"
"84.20000","3.50609","1010.64014"
"84.40000","3.51444","1015.47803"
"84.60000","3.52278","1020.04150"
"84.80000","3.53112","1024.94385"
"85.00000","3.53943","1029.92297"
"85.20000","3.54776","1034.88379"
"85.40000","3.55610","1039.62390"
"85.60000","3.56444","1044.68896"
"85.80000","3.57279","1049.34375"
"86.00000","3.58114","1053.97974"
"86.20000","3.58942","1058.81738"
"86.40000","3.59772","1063.58789"
"86.60000","3.60610","1068.02319"
"86.80000","3.61447","1073.02283"
"87.00000","3.62279","1077.80225"
"87.20000","3.63108","1082.61865"
"87.40000","3.63942","1087.09570"
"87.60000","3.64780","1091.75366"
"87.80000","3.65613","1096.01477"
"88.00000","3.66442","1100.86755"
"88.20000","3.67273","1105.63013"
"88.40000","3.68109","1110.40332"
"88.60000","3.68944","1115.18433"
"88.80000","3.69781","1119.67078"
"89.00000","3.70610","1123.95728"
"89.20000","3.71442","1128.53796"
"89.40000","3.72277","1133.05725"
"89.60000","3.73111","1137.89172"
"89.80000","3.73945","1142.25647"
"90.00000","3.74775","1146.92786"
"90.20000","3.75607","1151.23511"
"90.40000","3.76444","1155.73254"
"90.60000","3.77281","1160.10400"
"90.80000","3.78113","1164.64185"
"91.00000","3.78944","1168.89478"
"91.20000","3.79777","1173.12781"
"91.40000","3.80611","1177.37769"
"91.60000","3.81445","1182.27649"
"91.80000","3.82274","1186.15271"
"92.00000","3.83106","1191.02832"
"92.20000","3.83944","1195.02637"
"92.40000","3.84780","1199.40845"
"92.60000","3.85613","1203.76050"
"92.80000","3.86444","1208.48572"
"93.00000","3.87277","1212.51001"
"93.20000","3.88109","1216.61060"
"93.40000","3.88942","1220.85828"
"93.60000","3.89775","1225.75549"
"93.80000","3.90608","1230.09766"
"94.00000","3.91443","1233.92493"
"94.20000","3.92279","1238.18811"
"94.40000","3.93112","1242.46765"
"94.60000","3.93947","1246.69104"
"94.80000","3.94777","1251.09961"
"95.00000","3.95606","1254.97205"
"95.20000","3.96441","1259.12964"
"95.40000","3.97277","1263.09900"
"95.60000","3.98110","1267.25220"
"95.80000","3.98943","1271.40771"
"96.00000","3.99777","1275.55286"
"96.20000","4.00616","1279.64490"
"96.40000","4.01448","1283.96448"
"96.60000","4.02276","1287.88672"
"96.80000","4.03107","1291.65283"
"97.00000","4.03939","1295.78381"
"97.20000","4.04776","1299.77893"
"97.40000","4.05611","1303.90698"
"97.60000","4.06444","1307.71899"
"97.80000","4.07277","1311.64575"
"98.00000","4.08114","1315.22766"
"98.20000","4.08947","1319.52161"
"98.40000","4.09778","1323.14465"
"98.60000","4.10608","1326.83997"
"98.80000","4.11438","1330.56641"
"99.00000","4.12275","1334.60376"
"99.20000","4.13113","1338.72839"
"99.40000","4.13948","1342.27087"
"99.60000","4.14779","1346.35730"
"99.80000","4.15611","1349.64429"
"100.00000","4.16446","1353.89868"
"100.20000","4.17279","1357.11633"
"100.40000","4.18107","1360.69189"
"100.60000","4.18939","1364.33252"
"100.80000","4.19775","1367.74268"
"101.00000","4.20612","1371.56946"
"101.20000","4.21446","1374.96545"
"101.40000","4.22277","1378.62720"
"101.60000","4.23111","1382.30591"
"101.80000","4.23946","1385.81287"
"102.00000","4.24777","1388.85059"
"102.20000","4.25608","1392.61658"
"102.40000","4.26440","1395.93030"
"102.60000","4.27276","1399.63684"
"102.80000","4.28112","1402.78821"
"103.00000","4.28946","1406.35242"
"103.20000","4.29783","1409.40674"
"103.40000","4.30610","1412.94617"
"103.60000","4.31441","1416.06458"
"103.80000","4.32278","1419.50574"
"104.00000","4.33111","1422.44275"
"104.20000","4.33943","1425.62329"
"104.40000","4.34775","1428.58838"
"104.60000","4.35608","1432.14722"
"104.80000","4.36447","1435.48413"
"105.00000","4.37280","1438.66589"
"105.20000","4.38110","1441.48987"
"105.40000","4.38941","1444.49878"
"105.60000","4.39774","1447.73572"
"105.80000","4.40611","1450.66309"
"106.00000","4.41445","1453.41980"
"106.20000","4.42276","1456.43018"
"106.40000","4.43108","1459.41272"
"106.60000","4.43945","1462.51990"
"106.80000","4.44778","1465.38525"
"107.00000","4.45612","1467.92944"
"107.20000","4.46443","1470.55994"
"107.40000","4.47274","1473.42529"
"107.60000","4.48108","1475.67871"
"107.80000","4.48947","1478.64307"
"108.00000","4.49779","1481.00305"
"108.20000","4.50611","1484.19336"
"108.40000","4.51441","1486.44824"
"108.60000","4.52279","1489.22961"
"108.80000","4.53113","1491.75256"
"109.00000","4.53942","1494.28320"
"109.20000","4.54772","1496.57214"
"109.40000","4.55608","1499.20764"
"109.60000","4.56445","1501.56970"
"109.80000","4.57280","1503.82935"
"110.00000","4.58110","1506.48999"
"110.20000","4.58942","1508.77222"
"110.40000","4.59777","1511.03308"
"110.60000","4.60612","1513.17322"
"110.80000","4.61441","1515.20605"
"111.00000","4.62273","1517.62000"
"111.20000","4.63110","1519.76306"
"111.40000","4.63944","1522.20349"
"111.60000","4.64779","1523.77148"
"111.80000","4.65612","1526.17517"
"112.00000","4.66444","1528.15002"
"112.20000","4.67274","1530.09631"
"112.40000","4.68109","1532.07153"
"112.60000","4.68942","1533.89917"
"112.80000","4.69776","1535.77710"
"113.00000","4.70610","1537.90320"
"113.20000","4.71443","1540.09436"
"113.40000","4.72282","1542.17542"
"113.60000","4.73114","1543.54932"
"113.80000","4.73944","1545.17957"
"114.00000","4.74775","1546.83423"
"114.20000","4.75605","1548.69751"
"114.40000","4.76443","1550.41577"
"114.60000","4.77278","1551.80493"
"114.80000","4.78108","1553.71741"
"115.00000","4.78943","1555.31787"
"115.20000","4.79780","1557.04248"
"115.40000","4.80613","1558.52893"
"115.60000","4.81445","1560.08923"
"115.80000","4.82277","1561.51978"
"116.00000","4.83106","1562.61206"
"116.20000","4.83939","1564.34338"
"116.40000","4.84777","1565.78870"
"116.60000","4.85613","1567.48877"
"116.80000","4.86445","1568.43665"
"117.00000","4.87277","1569.76672"
"117.20000","4.88113","1571.30933"
"117.40000","4.88946","1572.41211"
"117.60000","4.89778","1574.09314"
"117.80000","4.90607","1575.20032"
"118.00000","4.91440","1576.57910"
"118.20000","4.92276","1577.90002"
"118.40000","4.93112","1579.41980"
"118.60000","4.93943","1580.33057"
"118.80000","4.94777","1581.37927"
"119.00000","4.95611","1582.75305"
"119.20000","4.96448","1583.69812"
"119.40000","4.97276","1584.80835"
"119.60000","4.98106","1585.98975"
"119.80000","4.98941","1586.79541"
"120.00000","4.99777","1587.93909"
"120.20000","5.00611","1589.12219"
"120.40000","5.01447","1590.52283"
"120.60000","5.02276","1591.06213"
"120.80000","5.03111","1592.18213"
"121.00000","5.03947","1593.20264"
"121.20000","5.04778","1594.08936"
"121.40000","5.05610","1595.11426"
"121.60000","5.06441","1595.84534"
"121.80000","5.07273","1596.93542"
"122.00000","5.08111","1598.15430"
"122.20000","5.08947","1598.88306"
"122.40000","5.09778","1599.93665"
"122.60000","5.10609","1600.86511"
"122.80000","5.11441","1601.61597"
"123.00000","5.12279","1602.33691"
"123.20000","5.13110","1603.25806"
"123.40000","5.13940","1603.92114"
"123.60000","5.14774","1604.72266"
"123.80000","5.15610","1605.82458"
"124.00000","5.16445","1606.50403"
"124.20000","5.17279","1607.13391"
"124.40000","5.18111","1607.73901"
"124.60000","5.18942","1608.41882"
"124.80000","5.19775","1609.26770"
"125.00000","5.20611","1609.84045"
"125.20000","5.21445","1610.64209"
"125.40000","5.22277","1611.20422"
"125.60000","5.23109","1611.75378"
"125.80000","5.23945","1612.79004"
"126.00000","5.24780","1613.51172"
"126.20000","5.25612","1614.01343"
"126.40000","5.26439","1614.22791"
"126.60000","5.27272","1614.89038"
"126.80000","5.28110","1615.75012"
"127.00000","5.28947","1616.37866"
"127.20000","5.29778","1616.84607"
"127.40000","5.30608","1617.56165"
"127.60000","5.31444","1618.02209"
"127.80000","5.32280","1618.38049"
"128.00000","5.33111","1618.85876"
"128.20000","5.33940","1619.56543"
"128.40000","5.34774","1619.84204"
"128.60000","5.35610","1620.98730"
"128.80000","5.36445","1621.47583"
"129.00000","5.37281","1621.75085"
"129.20000","5.38111","1622.33777"
"129.40000","5.38943","1622.79626"
"129.60000","5.39777","1623.41138"
"129.80000","5.40608","1623.43140"
"130.00000","5.41443","1624.15820"
"130.20000","5.42275","1624.47595"
"130.40000","5.43109","1625.08850"
"130.60000","5.43947","1625.44702"
"130.80000","5.44782","1625.66821"
"131.00000","5.45612","1626.16272"
"131.20000","5.46443","1626.59009"
"131.40000","5.47274","1626.57581"
"131.60000","5.48109","1627.06030"
"131.80000","5.48943","1627.15308"
"132.00000","5.49773","1627.27905"
"132.20000","5.50610","1627.56470"
"132.40000","5.51447","1627.98914"
"132.60000","5.52282","1628.34558"
"132.80000","5.53113","1628.12195"
"133.00000","5.53945","1628.69861"
"133.20000","5.54775","1628.76526"
"133.40000","5.55605","1628.83704"
"133.60000","5.56442","1628.80774"
"133.80000","5.57277","1628.84155"
"134.00000","5.58111","1629.03015"
"134.20000","5.58945","1628.82495"
"134.40000","5.59779","1629.21716"
"134.60000","5.60614","1628.98193"
"134.80000","5.61446","1628.92578"
"135.00000","5.62276","1629.09277"
"135.20000","5.63105","1629.07581"
"135.40000","5.63941","1628.97778"
"135.60000","5.64777","1629.07556"
"135.80000","5.65610","1628.98474"
"136.00000","5.66443","1628.83325"
"136.20000","5.67279","1628.71509"
"136.40000","5.68116","1628.94983"
"136.60000","5.68945","1628.96814"
"136.80000","5.69772","1629.00781"
"137.00000","5.70607","1629.22156"
"137.20000","5.71442","1628.78870"
"137.40000","5.72276","1628.96277"
"137.60000","5.73111","1628.89453"
"137.80000","5.73944","1628.93518"
"138.00000","5.74778","1628.69287"
"138.20000","5.75615","1628.79541"
"138.40000","5.76445","1628.92297"
"138.60000","5.77276","1628.44861"
"138.80000","5.78108","1628.32434"
"139.00000","5.78939","1628.59167"
"139.20000","5.79776","1628.24927"
"139.40000","5.80614","1628.22253"
"139.60000","5.81446","1628.12512"
"139.80000","5.82276","1628.11121"
"140.00000","5.83111","1627.51599"
"140.20000","5.83947","1627.78503"
"140.40000","5.84777","1627.84460"
"140.60000","5.85606","1627.29431"
"140.80000","5.86439","1627.21521"
"141.00000","5.87277","1627.01746"
"141.20000","5.88112","1626.55701"
"141.40000","5.88946","1626.83289"
"141.60000","5.89778","1626.34058"
"141.80000","5.90610","1626.02368"
"142.00000","5.91442","1625.78809"
"142.20000","5.92277","1625.26135"
"142.40000","5.93110","1624.97876"
"142.60000","5.93944","1624.58789"
"142.80000","5.94778","1624.05701"
"143.00000","5.95610","1623.38525"
"143.20000","5.96446","1623.45935"
"143.40000","5.97281","1622.57874"
"143.60000","5.98109","1622.02466"
"143.80000","5.98940","1621.14392"
"144.00000","5.99777","1620.63464"
"144.20000","6.00612","1619.92126"
"144.40000","6.01445","1619.13623"
"144.60000","6.02276","1618.17053"
"144.80000","6.03108","1617.23010"
"145.00000","6.03947","1616.66443"
"145.20000","6.04780","1615.60376"
"145.40000","6.05608","1614.32837"
"145.60000","6.06441","1613.40894"
"145.80000","6.07276","1612.09460"
"146.00000","6.08111","1611.21570"
"146.20000","6.08946","1609.88892"
"146.40000","6.09778","1608.83447"
"146.60000","6.10609","1607.29041"
"146.80000","6.11444","1605.82349"
"147.00000","6.12278","1604.31567"
"147.20000","6.13111","1602.51501"
"147.40000","6.13942","1600.98315"
"147.60000","6.14774","1598.93774"
"147.80000","6.15611","1597.44519"
"148.00000","6.16448","1595.63184"
"148.20000","6.17278","1593.61316"
"148.40000","6.18109","1591.44556"
"148.60000","6.18943","1589.13086"
"148.80000","6.19777","1586.88367"
"149.00000","6.20611","1584.48828"
"149.20000","6.21442","1581.78931"
"149.40000","6.22273","1579.76184"
"149.60000","6.23111","1577.15186"
"149.80000","6.23947","1574.46594"
"150.00000","6.24779","1571.76343"
"150.20000","6.25611","1568.89990"
"150.40000","6.26443","1566.15173"
"150.60000","6.27274","1563.35168"
"150.80000","6.28109","1560.55750"
"151.00000","6.28942","1557.63855"
"151.20000","6.29775","1554.58337"
"151.40000","6.30610","1551.58594"
"151.60000","6.31446","1549.26794"
"151.80000","6.32279","1546.13586"
"152.00000","6.33114","1543.08752"
"152.20000","6.33944","1540.28687"
"152.40000","6.34774","1536.85291"
"152.60000","6.35607","1533.99915"
"152.80000","6.36442","1530.99475"
"153.00000","6.37277","1528.21838"
"153.20000","6.38111","1525.50073"
"153.40000","6.38944","1522.45325"
"153.60000","6.39781","1520.12939"
"153.80000","6.40613","1517.65625"
"154.00000","6.41441","1514.91663"
"154.20000","6.42273","1512.07336"
"154.40000","6.43107","1509.75342"
"154.60000","6.43943","1507.44202"
"154.80000","6.44778","1504.49060"
"155.00000","6.45611","1502.20679"
"155.20000","6.46444","1499.63684"
"155.40000","6.47281","1497.18750"
"155.60000","6.48113","1495.06372"
"155.80000","6.48945","1492.74060"
"156.00000","6.49776","1490.48877"
"156.20000","6.50605","1488.11853"
"156.40000","6.51441","1486.39343"
"156.60000","6.52281","1484.24585"
"156.80000","6.53113","1482.22449"
"157.00000","6.53944","1480.38965"
"157.08700","6.54303","1478.98181"