File: MaterialsTesting/Specimen_RawData_2.csv
Time,Extension,Load
(s),(mm),(N)
"0.00000","0.00000","0.06623"
"0.20000","0.00611","0.11961"
"0.40000","0.01448","0.07006"
"0.60000","0.02280","-0.16643"
"0.80000","0.03114","-0.01612"
"1.00000","0.03946","0.03658"
"1.20000","0.04777","-0.12724"
"1.40000","0.05611","-0.30789"
"1.60000","0.06448","-0.14212"
"1.80000","0.07282","0.13049"
"2.00000","0.08114","0.22976"
"2.20000","0.08947","0.17092"
"2.40000","0.09779","-0.01525"
"2.60000","0.10615","-0.03855"
"2.80000","0.11448","0.30376"
"3.00000","0.12279","-0.15849"
"3.20000","0.13111","-0.18342"
"3.40000","0.13948","-0.06643"
"3.60000","0.14782","-0.00700"
"3.80000","0.15613","-0.17211"
"4.00000","0.16445","0.06152"
"4.20000","0.17280","-0.07343"
"4.40000","0.18117","0.04091"
"4.60000","0.18946","-0.22272"
"4.80000","0.19774","-0.12055"
"5.00000","0.20612","-0.03763"
"5.20000","0.21447","0.08959"
"5.40000","0.22281","0.03309"
"5.60000","0.23115","0.11637"
"5.80000","0.23946","-0.04781"
"6.00000","0.24779","-0.24652"
"6.20000","0.25615","-0.01696"
"6.40000","0.26449","-0.02012"
"6.60000","0.27280","0.30818"
"6.80000","0.28112","0.16597"
"7.00000","0.28942","-0.22634"
"7.20000","0.29779","-0.06345"
"7.40000","0.30618","-0.08136"
"7.60000","0.31448","-0.25413"
"7.80000","0.32279","0.31894"
"8.00000","0.33113","-0.18638"
"8.20000","0.33948","-0.19096"
"8.40000","0.34781","0.01914"
"8.60000","0.35611","-0.05894"
"8.80000","0.36443","0.12451"
"9.00000","0.37280","-0.07506"
"9.20000","0.38115","-0.12390"
"9.40000","0.38948","-0.04517"
"9.60000","0.39780","-0.10456"
"9.80000","0.40612","0.11319"
"10.00000","0.41446","-0.30073"
"10.20000","0.42282","-0.18968"
"10.40000","0.43114","0.27776"
"10.60000","0.43946","-0.10180"
"10.80000","0.44780","0.08606"
"11.00000","0.45613","-0.04859"
"11.20000","0.46448","-0.03104"
"11.40000","0.47282","0.17143"
"11.60000","0.48109","0.17972"
"11.80000","0.48943","-0.00374"
"12.00000","0.49781","-0.06312"
"12.20000","0.50616","-0.25678"
"12.40000","0.51448","-0.03188"
"12.60000","0.52279","0.09494"
"12.80000","0.53112","0.05771"
"13.00000","0.53949","-0.04016"
"13.20000","0.54780","-0.35662"
"13.40000","0.55608","-0.02829"
"13.60000","0.56444","0.00314"
"13.80000","0.57280","0.05856"
"14.00000","0.58116","-0.17482"
"14.20000","0.58950","-0.04966"
"14.40000","0.59782","-0.12712"
"14.60000","0.60613","-0.26071"
"14.80000","0.61446","0.11954"
"15.00000","0.62279","-0.15545"
"15.20000","0.63111","-0.02997"
"15.40000","0.63944","-0.16238"
"15.60000","0.64777","-0.20275"
"15.80000","0.65616","-0.09948"
"16.00000","0.66452","-0.03100"
"16.20000","0.67283","0.08258"
"16.40000","0.68113","0.01288"
"16.60000","0.68945","-0.00590"
"16.80000","0.69779","0.05940"
"17.00000","0.70612","-0.02719"
"17.20000","0.71444","-0.07190"
"17.40000","0.72277","-0.19599"
"17.60000","0.73115","-0.25270"
"17.80000","0.73951","0.12483"
"18.00000","0.74782","-0.07823"
"18.20000","0.75615","-0.05559"
"18.40000","0.76446","-0.05978"
"18.60000","0.77276","-0.06027"
"18.80000","0.78111","0.13673"
"19.00000","0.78945","-0.01158"
"19.20000","0.79779","-0.25944"
"19.40000","0.80614","-0.15104"
"19.60000","0.81448","-0.09076"
"19.80000","0.82282","-0.10508"
"20.00000","0.83118","0.04534"
"20.20000","0.83946","-0.05150"
"20.40000","0.84776","0.26125"
"20.60000","0.85611","-0.14739"
"20.80000","0.86447","-0.09598"
"21.00000","0.87280","0.03349"
"21.20000","0.88113","0.15975"
"21.40000","0.88947","0.05997"
"21.60000","0.89786","0.20644"
"21.80000","0.90615","-0.01445"
"22.00000","0.91443","-0.16561"
"22.20000","0.92275","-0.06248"
"22.40000","0.93111","-0.07359"
"22.60000","0.93947","0.00557"
"22.80000","0.94782","-0.16108"
"23.00000","0.95613","-0.07882"
"23.20000","0.96447","-0.11059"
"23.40000","0.97282","-0.26501"
"23.60000","0.98116","0.04805"
"23.80000","0.98947","0.00511"
"24.00000","0.99778","-0.29479"
"24.20000","1.00608","0.05230"
"24.40000","1.01445","-0.15452"
"24.60000","1.02283","-0.11414"
"24.80000","1.03116","-0.18319"
"25.00000","1.03946","-0.27521"
"25.20000","1.04779","-0.03462"
"25.40000","1.05616","0.36472"
"25.60000","1.06449","0.10829"
"25.80000","1.07277","0.14404"
"26.00000","1.08109","-0.09646"
"26.20000","1.08946","-0.08640"
"26.40000","1.09782","0.08055"
"26.60000","1.10615","0.04178"
"26.80000","1.11446","0.04183"
"27.00000","1.12280","0.01928"
"27.20000","1.13114","0.03259"
"27.40000","1.13948","-0.07404"
"27.60000","1.14779","0.15213"
"27.80000","1.15611","0.19627"
"28.00000","1.16447","0.20265"
"28.20000","1.17280","0.08799"
"28.40000","1.18115","-0.20825"
"28.60000","1.18950","0.00396"
"28.80000","1.19780","0.09889"
"29.00000","1.20609","-0.09963"
"29.20000","1.21447","0.07573"
"29.40000","1.22282","0.11549"
"29.60000","1.23115","-0.10400"
"29.80000","1.23944","0.00969"
"30.00000","1.24778","0.12674"
"30.20000","1.25616","0.03613"
"30.40000","1.26449","-0.05117"
"30.60000","1.27278","0.21128"
"30.80000","1.28111","-0.07295"
"31.00000","1.28946","0.01738"
"31.20000","1.29782","0.18812"
"31.40000","1.30617","0.33676"
"31.60000","1.31446","0.16268"
"31.80000","1.32278","-0.25890"
"32.00000","1.33115","-0.04312"
"32.20000","1.33948","0.09224"
"32.40000","1.34781","0.23573"
"32.60000","1.35612","0.12463"
"32.80000","1.36443","0.14563"
"33.00000","1.37280","0.24144"
"33.20000","1.38118","0.18368"
"33.40000","1.38949","0.19389"
"33.60000","1.39780","-0.15491"
"33.80000","1.40612","0.25144"
"34.00000","1.41448","0.10048"
"34.20000","1.42281","-0.14319"
"34.40000","1.43111","0.09482"
"34.60000","1.43942","-0.01875"
"34.80000","1.44780","0.13306"
"35.00000","1.45616","0.00647"
"35.20000","1.46450","-0.00403"
"35.40000","1.47281","0.15564"
"35.60000","1.48112","0.04513"
"35.80000","1.48945","-0.14182"
"36.00000","1.49779","-0.07435"
"36.20000","1.50612","-0.05215"
"36.40000","1.51445","0.11930"
"36.60000","1.52280","-0.00590"
"36.80000","1.53114","0.24372"
"37.00000","1.53948","-0.10236"
"37.20000","1.54784","-0.08065"
"37.40000","1.55614","0.24582"
"37.60000","1.56444","0.10589"
"37.80000","1.57277","-0.16874"
"38.00000","1.58112","0.06214"
"38.20000","1.58947","0.08419"
"38.40000","1.59778","-0.04667"
"38.60000","1.60614","0.14103"
"38.80000","1.61451","-0.13648"
"39.00000","1.62283","-0.10537"
"39.20000","1.63112","-0.13942"
"39.40000","1.63944","0.08387"
"39.60000","1.64777","0.10156"
"39.80000","1.65612","0.20596"
"40.00000","1.66448","-0.19601"
"40.20000","1.67279","-0.15942"
"40.40000","1.68114","0.33773"
"40.60000","1.68951","-0.13221"
"40.80000","1.69783","0.05642"
"41.00000","1.70613","0.06316"
"41.20000","1.71444","0.23905"
"41.40000","1.72273","0.14000"
"41.60000","1.73111","0.34851"
"41.80000","1.73950","0.24717"
"42.00000","1.74783","-0.19232"
"42.20000","1.75615","-0.24898"
"42.40000","1.76447","0.16893"
"42.60000","1.77282","0.96825"
"42.80000","1.78115","0.69146"
"43.00000","1.78942","1.44427"
"43.20000","1.79775","2.03063"
"43.40000","1.80611","2.06770"
"43.60000","1.81447","2.45548"
"43.80000","1.82283","2.55161"
"44.00000","1.83115","3.11210"
"44.20000","1.83947","3.76341"
"44.40000","1.84782","4.19415"
"44.60000","1.85614","5.23402"
"44.80000","1.86444","6.25474"
"45.00000","1.87277","7.01299"
"45.20000","1.88112","8.36932"
"45.40000","1.88947","10.71668"
"45.60000","1.89782","12.88372"
"45.80000","1.90618","15.29985"
"46.00000","1.91448","17.57932"
"46.20000","1.92278","19.96463"
"46.40000","1.93114","23.22886"
"46.60000","1.93947","25.81721"
"46.80000","1.94779","28.39911"
"47.00000","1.95612","31.04193"
"47.20000","1.96444","33.78503"
"47.40000","1.97282","36.71810"
"47.60000","1.98117","39.39786"
"47.80000","1.98946","42.64408"
"48.00000","1.99779","45.35182"
"48.20000","2.00611","48.31640"
"48.40000","2.01447","50.74170"
"48.60000","2.02280","53.65439"
"48.80000","2.03112","56.90538"
"49.00000","2.03944","59.66654"
"49.20000","2.04781","62.35830"
"49.40000","2.05614","65.10323"
"49.60000","2.06448","67.95290"
"49.80000","2.07279","70.68296"
"50.00000","2.08110","73.66900"
"50.20000","2.08945","76.75281"
"50.40000","2.09783","79.77374"
"50.60000","2.10615","82.87742"
"50.80000","2.11447","85.61853"
"51.00000","2.12279","89.14548"
"51.20000","2.13115","92.35244"
"51.40000","2.13949","95.35793"
"51.60000","2.14779","98.77634"
"51.80000","2.15607","102.06324"
"52.00000","2.16443","105.23804"
"52.20000","2.17282","109.05471"
"52.40000","2.18117","112.58874"
"52.60000","2.18948","116.15464"
"52.80000","2.19778","119.72850"
"53.00000","2.20613","123.12495"
"53.20000","2.21448","126.75314"
"53.40000","2.22278","130.35623"
"53.60000","2.23111","133.83083"
"53.80000","2.23947","137.55084"
"54.00000","2.24780","140.92693"
"54.20000","2.25615","144.64667"
"54.40000","2.26448","148.43317"
"54.60000","2.27281","151.97701"
"54.80000","2.28112","155.97852"
"55.00000","2.28946","159.46242"
"55.20000","2.29779","163.39391"
"55.40000","2.30613","167.26587"
"55.60000","2.31445","171.25537"
"55.80000","2.32279","175.13658"
"56.00000","2.33117","179.11299"
"56.20000","2.33950","182.77798"
"56.40000","2.34781","186.40089"
"56.60000","2.35612","190.55130"
"56.80000","2.36443","194.48283"
"57.00000","2.37278","198.30409"
"57.20000","2.38114","202.53564"
"57.40000","2.38946","206.67445"
"57.60000","2.39780","211.05632"
"57.80000","2.40617","215.13637"
"58.00000","2.41450","219.42439"
"58.20000","2.42281","223.77327"
"58.40000","2.43112","227.89941"
"58.60000","2.43944","232.39395"
"58.80000","2.44776","236.51364"
"59.00000","2.45614","240.82016"
"59.20000","2.46448","245.68523"
"59.40000","2.47281","249.73456"
"59.60000","2.48113","254.40211"
"59.80000","2.48948","258.64032"
"60.00000","2.49783","263.10959"
"60.20000","2.50613","267.69763"
"60.40000","2.51443","272.25308"
"60.60000","2.52275","277.01913"
"60.80000","2.53112","281.42752"
"61.00000","2.53949","286.14847"
"61.20000","2.54780","290.99445"
"61.40000","2.55613","295.95453"
"61.60000","2.56449","301.06979"
"61.80000","2.57285","306.26688"
"62.00000","2.58113","311.17218"
"62.20000","2.58942","316.59824"
"62.40000","2.59776","321.61957"
"62.60000","2.60612","327.16827"
"62.80000","2.61446","332.75623"
"63.00000","2.62284","338.08841"
"63.20000","2.63114","343.46912"
"63.40000","2.63947","349.22433"
"63.60000","2.64783","354.49927"
"63.80000","2.65613","360.18643"
"64.00000","2.66446","365.83313"
"64.20000","2.67278","371.75580"
"64.40000","2.68109","377.66263"
"64.60000","2.68947","383.43793"
"64.80000","2.69784","388.86081"
"65.00000","2.70614","394.85580"
"65.20000","2.71446","400.54272"
"65.40000","2.72280","406.59555"
"65.60000","2.73114","412.34460"
"65.80000","2.73947","418.28223"
"66.00000","2.74777","424.09705"
"66.20000","2.75611","429.96912"
"66.40000","2.76448","436.12985"
"66.60000","2.77281","442.10107"
"66.80000","2.78114","448.21460"
"67.00000","2.78947","454.14584"
"67.20000","2.79778","459.76788"
"67.40000","2.80613","466.10303"
"67.60000","2.81448","472.04340"
"67.80000","2.82280","477.96762"
"68.00000","2.83113","484.08011"
"68.20000","2.83946","490.23138"
"68.40000","2.84781","496.54102"
"68.60000","2.85617","501.92282"
"68.80000","2.86448","508.55008"
"69.00000","2.87274","514.46747"
"69.20000","2.88108","520.42798"
"69.40000","2.88947","526.48541"
"69.60000","2.89785","532.99255"
"69.80000","2.90616","538.74811"
"70.00000","2.91445","544.52429"
"70.20000","2.92279","551.02081"
"70.40000","2.93116","556.73511"
"70.60000","2.93946","562.92584"
"70.80000","2.94775","568.86200"
"71.00000","2.95610","574.66095"
"71.20000","2.96446","580.93213"
"71.40000","2.97281","587.06445"
"71.60000","2.98117","593.26782"
"71.80000","2.98948","599.39093"
"72.00000","2.99779","605.76062"
"72.20000","3.00613","611.87708"
"72.40000","3.01444","618.35248"
"72.60000","3.02279","625.06122"
"72.80000","3.03111","631.44525"
"73.00000","3.03944","638.16040"
"73.20000","3.04783","644.44458"
"73.40000","3.05620","651.43036"
"73.60000","3.06449","657.98431"
"73.80000","3.07280","664.92767"
"74.00000","3.08112","671.38184"
"74.20000","3.08944","678.13031"
"74.40000","3.09779","684.57275"
"74.60000","3.10610","691.79694"
"74.80000","3.11444","698.23822"
"75.00000","3.12283","705.21576"
"75.20000","3.13118","712.10626"
"75.40000","3.13949","718.66449"
"75.60000","3.14780","725.29773"
"75.80000","3.15612","732.06989"
"76.00000","3.16443","738.76929"
"76.20000","3.17278","745.55206"
"76.40000","3.18112","752.09235"
"76.60000","3.18946","759.02411"
"76.80000","3.19781","765.60388"
"77.00000","3.20616","772.46234"
"77.20000","3.21449","778.90106"
"77.40000","3.22283","785.58148"
"77.60000","3.23111","792.41626"
"77.80000","3.23942","798.94415"
"78.00000","3.24779","805.29724"
"78.20000","3.25614","812.09149"
"78.40000","3.26446","818.43036"
"78.60000","3.27279","824.77704"
"78.80000","3.28114","831.52802"
"79.00000","3.28951","837.67059"
"79.20000","3.29782","844.22095"
"79.40000","3.30610","850.77740"
"79.60000","3.31442","857.12866"
"79.80000","3.32277","863.47498"
"80.00000","3.33113","869.61359"
"80.20000","3.33949","875.90881"
"80.40000","3.34780","882.34943"
"80.60000","3.35614","888.36090"
"80.80000","3.36451","894.55176"
"81.00000","3.37282","900.10858"
"81.20000","3.38113","906.45508"
"81.40000","3.38945","912.53638"
"81.60000","3.39776","918.14948"
"81.80000","3.40612","923.76428"
"82.00000","3.41449","929.26465"
"82.20000","3.42283","934.97784"
"82.40000","3.43114","940.40063"
"82.60000","3.43946","945.81024"
"82.80000","3.44782","951.22296"
"83.00000","3.45614","956.24976"
"83.20000","3.46443","961.16394"
"83.40000","3.47276","966.19104"
"83.60000","3.48114","971.34845"
"83.80000","3.48948","976.16711"
"84.00000","3.49781","980.84576"
"84.20000","3.50613","985.55737"
"84.40000","3.51448","990.31732"
"84.60000","3.52281","994.75031"
"84.80000","3.53114","999.07971"
"85.00000","3.53946","1003.19299"
"85.20000","3.54779","1007.80792"
"85.40000","3.55613","1012.01440"
"85.60000","3.56447","1016.61523"
"85.80000","3.57281","1020.57324"
"86.00000","3.58117","1024.53284"
"86.20000","3.58945","1028.02539"
"86.40000","3.59775","1032.26025"
"86.60000","3.60614","1036.27234"
"86.80000","3.61450","1040.06226"
"87.00000","3.62282","1043.53833"
"87.20000","3.63111","1047.02905"
"87.40000","3.63944","1050.76160"
"87.60000","3.64783","1054.63574"
"87.80000","3.65616","1057.93713"
"88.00000","3.66444","1061.29407"
"88.20000","3.67276","1064.35498"
"88.40000","3.68112","1068.36096"
"88.60000","3.68947","1071.80615"
"88.80000","3.69784","1074.86987"
"89.00000","3.70613","1078.09924"
"89.20000","3.71445","1081.72314"
"89.40000","3.72281","1084.49683"
"89.60000","3.73114","1088.25598"
"89.80000","3.73947","1091.45410"
"90.00000","3.74778","1094.04333"
"90.20000","3.75610","1097.09290"
"90.40000","3.76447","1100.31360"
"90.60000","3.77284","1103.67261"
"90.80000","3.78116","1106.70044"
"91.00000","3.78947","1109.65442"
"91.20000","3.79779","1112.51685"
"91.40000","3.80614","1115.41382"
"91.60000","3.81448","1118.54688"
"91.80000","3.82277","1121.23779"
"92.00000","3.83109","1124.04529"
"92.20000","3.83946","1127.30505"
"92.40000","3.84783","1130.30774"
"92.60000","3.85616","1132.86218"
"92.80000","3.86447","1135.62671"
"93.00000","3.87279","1138.41931"
"93.20000","3.88113","1141.42297"
"93.40000","3.88944","1143.98352"
"93.60000","3.89778","1146.66504"
"93.80000","3.90611","1149.28589"
"94.00000","3.91446","1152.37280"
"94.20000","3.92282","1155.11621"
"94.40000","3.93115","1157.73108"
"94.60000","3.93951","1160.08997"
"94.80000","3.94780","1162.75769"
"95.00000","3.95610","1165.10681"
"95.20000","3.96445","1167.73315"
"95.40000","3.97280","1170.31970"
"95.60000","3.98114","1172.44421"
"95.80000","3.98945","1175.12732"
"96.00000","3.99779","1177.56482"
"96.20000","4.00618","1180.33862"
"96.40000","4.01450","1182.58984"
"96.60000","4.02279","1184.83337"
"96.80000","4.03110","1186.87256"
"97.00000","4.03943","1189.45532"
"97.20000","4.04779","1191.54175"
"97.40000","4.05614","1193.79700"
"97.60000","4.06447","1182.24585"
"97.80000","4.07280","1185.27283"
"98.00000","4.08117","1187.82166"
"98.20000","4.08949","1189.59973"
"98.40000","4.09781","1192.36670"
"98.60000","4.10611","1194.42285"
"98.80000","4.11441","1196.80542"
"99.00000","4.12277","1198.91614"
"99.20000","4.13116","1201.55542"
"99.40000","4.13950","1203.41003"
"99.60000","4.14781","1205.73743"
"99.80000","4.15615","1207.82361"
"100.00000","4.16449","1210.02710"
"100.20000","4.17281","1212.29614"
"100.40000","4.18109","1214.01636"
"100.60000","4.18940","1216.22827"
"100.80000","4.19778","1218.51367"
"101.00000","4.20615","1220.13452"
"101.20000","4.21449","1222.20691"
"101.40000","4.22281","1224.17432"
"101.60000","4.23114","1225.65796"
"101.80000","4.23949","1227.78467"
"102.00000","4.24781","1229.69604"
"102.20000","4.25611","1231.40100"
"102.40000","4.26443","1233.41785"
"102.60000","4.27279","1234.76733"
"102.80000","4.28115","1236.50146"
"103.00000","4.28949","1238.32642"
"103.20000","4.29785","1239.88550"
"103.40000","4.30615","1241.27515"
"103.60000","4.31443","1242.46558"
"103.80000","4.32281","1243.80127"
"104.00000","4.33114","1245.07190"
"104.20000","4.33947","1246.42236"
"104.40000","4.34778","1247.56116"
"104.60000","4.35610","1248.05713"
"104.80000","4.36449","1247.97876"
"105.00000","4.37284","1248.00854"
"105.20000","4.38113","1245.93042"
"105.40000","4.38944","1246.45789"
"105.60000","4.39777","1247.28540"
"105.80000","4.40614","1248.68066"
"106.00000","4.41448","1249.76770"
"106.20000","4.42279","1251.30737"
"106.40000","4.43111","1252.55737"
"106.60000","4.43948","1253.62842"
"106.80000","4.44781","1254.96313"
"107.00000","4.45615","1256.48901"
"107.20000","4.46446","1258.03137"
"107.40000","4.47277","1258.90198"
"107.60000","4.48111","1260.22498"
"107.80000","4.48950","1262.00769"
"108.00000","4.49781","1262.93164"
"108.20000","4.50614","1264.17090"
"108.40000","4.51444","1265.06726"
"108.60000","4.52282","1266.35522"
"108.80000","4.53116","1267.81299"
"109.00000","4.53946","1268.84290"
"109.20000","4.54775","1270.10095"
"109.40000","4.55611","1271.30676"
"109.60000","4.56448","1272.14661"
"109.80000","4.57284","1273.50720"
"110.00000","4.58114","1274.07837"
"110.20000","4.58945","1275.39612"
"110.40000","4.59780","1276.80176"
"110.60000","4.60615","1277.44714"
"110.80000","4.61444","1278.53455"
"111.00000","4.62276","1279.23157"
"111.20000","4.63113","1280.10083"
"111.40000","4.63948","1281.37451"
"111.60000","4.64782","1282.03418"
"111.80000","4.65616","1282.92615"
"112.00000","4.66447","1284.11768"
"112.20000","4.67277","1284.81921"
"112.40000","4.68112","1285.82922"
"112.60000","4.68945","1286.48523"
"112.80000","4.69779","1287.31494"
"113.00000","4.70612","1288.27795"
"113.20000","4.71446","1288.81763"
"113.40000","4.72284","1289.52686"
"113.60000","4.73117","1290.34412"
"113.80000","4.73947","1290.71082"
"114.00000","4.74778","1291.90063"
"114.20000","4.75609","1292.07458"
"114.40000","4.76445","1293.19861"
"114.60000","4.77282","1293.88977"
"114.80000","4.78111","1294.45178"
"115.00000","4.78946","1295.01196"
"115.20000","4.79783","1295.70276"
"115.40000","4.80616","1296.32642"
"115.60000","4.81448","1296.72485"
"115.80000","4.82280","1297.01746"
"116.00000","4.83109","1297.25037"
"116.20000","4.83943","1297.93921"
"116.40000","4.84780","1298.87610"
"116.60000","4.85616","1299.13562"
"116.80000","4.86449","1299.72949"
"117.00000","4.87280","1299.71790"
"117.20000","4.88116","1300.54199"
"117.40000","4.88950","1300.99036"
"117.60000","4.89781","1301.43091"
"117.80000","4.90610","1301.78308"
"118.00000","4.91443","1302.14258"
"118.20000","4.92280","1302.58997"
"118.40000","4.93115","1303.00623"
"118.60000","4.93946","1303.34973"
"118.80000","4.94780","1303.48596"
"119.00000","4.95615","1304.24780"
"119.20000","4.96451","1304.12427"
"119.40000","4.97279","1304.60840"
"119.60000","4.98108","1305.02271"
"119.80000","4.98945","1305.13977"
"120.00000","4.99780","1305.72742"
"120.20000","5.00614","1306.05469"
"120.40000","5.01450","1306.19861"
"120.60000","5.02280","1306.49316"
"120.80000","5.03113","1306.86328"
"121.00000","5.03949","1307.20825"
"121.20000","5.04781","1307.12732"
"121.40000","5.05613","1307.35986"
"121.60000","5.06444","1307.55371"
"121.80000","5.07276","1307.87207"
"122.00000","5.08114","1308.49902"
"122.20000","5.08949","1308.71887"
"122.40000","5.09782","1308.84692"
"122.60000","5.10612","1309.22461"
"122.80000","5.11445","1309.31396"
"123.00000","5.12282","1309.62451"
"123.20000","5.13113","1309.45837"
"123.40000","5.13943","1309.73523"
"123.60000","5.14776","1310.12219"
"123.80000","5.15613","1310.15906"
"124.00000","5.16447","1310.52881"
"124.20000","5.17282","1310.69836"
"124.40000","5.18115","1310.96045"
"124.60000","5.18945","1311.09900"
"124.80000","5.19778","1311.36316"
"125.00000","5.20615","1311.38171"
"125.20000","5.21448","1311.50818"
"125.40000","5.22281","1311.71899"
"125.60000","5.23112","1312.18933"
"125.80000","5.23948","1312.32385"
"126.00000","5.24784","1312.97192"
"126.20000","5.25615","1312.62561"
"126.40000","5.26443","1312.74548"
"126.60000","5.27275","1312.97607"
"126.80000","5.28114","1313.43323"
"127.00000","5.28950","1313.60303"
"127.20000","5.29781","1313.92859"
"127.40000","5.30612","1313.65698"
"127.60000","5.31445","1314.11218"
"127.80000","5.32283","1314.20288"
"128.00000","5.33114","1314.49988"
"128.20000","5.33943","1314.54468"
"128.40000","5.34777","1314.87305"
"128.60000","5.35613","1315.09680"
"128.80000","5.36448","1315.31958"
"129.00000","5.37284","1315.74463"
"129.20000","5.38115","1315.90540"
"129.40000","5.38945","1316.11157"
"129.60000","5.39781","1316.19177"
"129.80000","5.40612","1316.57056"
"130.00000","5.41446","1316.73743"
"130.20000","5.42278","1316.94214"
"130.40000","5.43111","1317.00574"
"130.60000","5.43950","1317.73669"
"130.80000","5.44785","1317.66895"
"131.00000","5.45616","1318.20520"
"131.20000","5.46446","1318.17102"
"131.40000","5.47277","1318.30994"
"131.60000","5.48112","1318.52661"
"131.80000","5.48946","1318.91016"
"132.00000","5.49777","1319.19238"
"132.20000","5.50612","1319.24475"
"132.40000","5.51450","1319.64417"
"132.60000","5.52285","1319.80396"
"132.80000","5.53117","1320.20972"
"133.00000","5.53947","1320.35315"
"133.20000","5.54778","1320.65381"
"133.40000","5.55608","1320.94690"
"133.60000","5.56445","1320.90527"
"133.80000","5.57279","1321.30615"
"134.00000","5.58114","1321.70264"
"134.20000","5.58947","1322.13513"
"134.40000","5.59782","1322.46765"
"134.60000","5.60617","1323.03186"
"134.80000","5.61450","1322.67859"
"135.00000","5.62279","1322.84961"
"135.20000","5.63108","1323.21973"
"135.40000","5.63944","1323.61877"
"135.60000","5.64780","1323.93518"
"135.80000","5.65613","1324.12854"
"136.00000","5.66447","1324.55652"
"136.20000","5.67282","1325.08545"
"136.40000","5.68119","1325.56482"
"136.60000","5.68948","1325.71997"
"136.80000","5.69775","1325.86951"
"137.00000","5.70609","1326.52283"
"137.20000","5.71445","1326.51270"
"137.40000","5.72279","1326.96899"
"137.60000","5.73115","1327.49280"
"137.80000","5.73947","1327.82092"
"138.00000","5.74781","1328.08313"
"138.20000","5.75618","1328.42859"
"138.40000","5.76448","1328.79297"
"138.60000","5.77279","1329.45837"
"138.80000","5.78111","1329.50867"
"139.00000","5.78942","1329.63989"
"139.20000","5.79779","1330.23035"
"139.40000","5.80616","1330.94482"
"139.60000","5.81449","1330.97595"
"139.80000","5.82280","1331.32410"
"140.00000","5.83114","1331.88550"
"140.20000","5.83949","1332.27185"
"140.40000","5.84781","1332.33643"
"140.60000","5.85609","1332.78821"
"140.80000","5.86442","1333.50366"
"141.00000","5.87281","1334.02319"
"141.20000","5.88115","1334.39832"
"141.40000","5.88949","1334.92249"
"141.60000","5.89781","1335.04822"
"141.80000","5.90613","1335.70618"
"142.00000","5.91445","1335.73865"
"142.20000","5.92280","1336.66321"
"142.40000","5.93113","1336.94177"
"142.60000","5.93946","1337.46497"
"142.80000","5.94781","1337.58667"
"143.00000","5.95614","1338.25220"
"143.20000","5.96448","1338.85437"
"143.40000","5.97283","1339.10278"
"143.60000","5.98112","1339.70569"
"143.80000","5.98942","1340.08154"
"144.00000","5.99780","1340.55029"
"144.20000","6.00616","1341.21069"
"144.40000","6.01448","1341.65393"
"144.60000","6.02279","1342.14978"
"144.80000","6.03111","1342.44006"
"145.00000","6.03950","1342.86328"
"145.20000","6.04783","1343.48376"
"145.40000","6.05611","1343.81323"
"145.60000","6.06444","1344.22839"
"145.80000","6.07279","1344.81055"
"146.00000","6.08115","1345.77490"
"146.20000","6.08949","1346.31726"
"146.40000","6.09781","1346.80518"
"146.60000","6.10612","1347.38330"
"146.80000","6.11447","1347.59180"
"147.00000","6.12280","1348.59180"
"147.20000","6.13113","1348.91040"
"147.40000","6.13945","1349.41626"
"147.60000","6.14776","1349.91541"
"147.80000","6.15613","1350.43372"
"148.00000","6.16451","1351.15894"
"148.20000","6.17281","1351.72144"
"148.40000","6.18112","1352.18835"
"148.60000","6.18946","1352.88306"
"148.80000","6.19781","1353.16858"
"149.00000","6.20614","1353.79443"
"149.20000","6.21444","1354.56995"
"149.40000","6.22277","1354.96826"
"149.60000","6.23114","1355.59998"
"149.80000","6.23951","1356.40210"
"150.00000","6.24783","1357.07129"
"150.20000","6.25613","1357.16492"
"150.40000","6.26446","1358.21191"
"150.60000","6.27277","1358.62195"
"150.80000","6.28113","1359.19824"
"151.00000","6.28945","1359.70923"
"151.20000","6.29778","1360.32397"
"151.40000","6.30614","1361.05945"
"151.60000","6.31449","1361.67126"
"151.80000","6.32282","1362.25842"
"152.00000","6.33117","1362.89270"
"152.20000","6.33947","1363.41125"
"152.40000","6.34776","1364.00830"
"152.60000","6.35610","1364.62817"
"152.80000","6.36445","1365.37756"
"153.00000","6.37280","1366.15271"
"153.20000","6.38114","1366.61572"
"153.40000","6.38947","1367.50964"
"153.60000","6.39784","1368.42957"
"153.80000","6.40617","1369.00317"
"154.00000","6.41444","1369.75513"
"154.20000","6.42277","1370.21008"
"154.40000","6.43110","1371.41663"
"154.60000","6.43946","1371.80884"
"154.80000","6.44782","1372.51990"
"155.00000","6.45614","1373.09155"
"155.20000","6.46447","1374.01294"
"155.40000","6.47285","1374.51111"
"155.60000","6.48116","1375.24341"
"155.80000","6.48948","1376.20215"
"156.00000","6.49778","1376.37378"
"156.20000","6.50609","1377.22571"
"156.40000","6.51444","1378.50830"
"156.60000","6.52283","1379.09656"
"156.80000","6.53115","1379.78906"
"157.00000","6.53947","1380.73926"
"157.20000","6.54780","1381.05737"
"157.40000","6.55616","1381.63171"
"157.60000","6.56448","1382.93066"
"157.80000","6.57279","1383.45850"
"158.00000","6.58109","1384.11316"
"158.20000","6.58945","1385.21289"
"158.40000","6.59781","1385.76514"
"158.60000","6.60616","1386.56628"
"158.80000","6.61447","1387.19531"
"159.00000","6.62281","1388.34729"
"159.20000","6.63115","1388.72241"
"159.40000","6.63948","1389.73767"
"159.60000","6.64778","1390.22791"
"159.80000","6.65611","1391.52002"
"160.00000","6.66446","1391.77356"
"160.20000","6.67280","1392.86108"
"160.40000","6.68115","1393.60388"
"160.60000","6.68951","1394.46985"
"160.80000","6.69779","1395.37134"
"161.00000","6.70610","1395.76282"
"161.20000","6.71447","1396.87219"
"161.40000","6.72280","1397.12378"
"161.60000","6.73114","1398.32117"
"161.80000","6.73946","1398.85901"
"162.00000","6.74777","1399.67908"
"162.20000","6.75616","1400.61133"
"162.40000","6.76452","1401.59656"
"162.60000","6.77279","1402.30872"
"162.80000","6.78110","1403.51294"
"163.00000","6.78944","1403.92566"
"163.20000","6.79780","1404.73865"
"163.40000","6.80615","1406.09814"
"163.60000","6.81446","1406.45667"
"163.80000","6.82279","1407.62732"
"164.00000","6.83115","1408.57336"
"164.20000","6.83948","1408.57898"
"164.40000","6.84781","1409.80054"
"164.60000","6.85612","1410.77917"
"164.80000","6.86443","1411.81274"
"165.00000","6.87278","1412.24536"
"165.20000","6.88117","1413.47571"
"165.40000","6.88948","1414.00854"
"165.60000","6.89781","1414.94336"
"165.80000","6.90613","1415.74072"
"166.00000","6.91448","1416.60913"
"166.20000","6.92283","1417.51697"
"166.40000","6.93112","1417.95459"
"166.60000","6.93941","1418.91260"
"166.80000","6.94778","1420.01318"
"167.00000","6.95615","1421.09058"
"167.20000","6.96450","1421.89929"
"167.40000","6.97280","1422.46973"
"167.60000","6.98112","1423.02625"
"167.80000","6.98946","1424.03772"
"168.00000","6.99781","1424.89685"
"168.13600","7.00350","1425.56775"