File: MaterialsTesting/Specimen_RawData_4.csv
Time,Extension,Load
(s),(mm),(N)
"0.00000","0.00000","0.01860"
"0.10000","0.00126","-0.25513"
"0.20000","0.00554","-0.07007"
"0.30000","0.00987","0.27656"
"0.40000","0.01411","0.23184"
"0.50000","0.01824","0.03676"
"0.60000","0.02245","0.03193"
"0.70000","0.02660","0.36752"
"0.80000","0.03077","-0.06368"
"0.90000","0.03494","0.24272"
"1.00000","0.03909","0.08083"
"1.10000","0.04325","-0.17190"
"1.20000","0.04741","-0.10720"
"1.30000","0.05157","-0.13350"
"1.40000","0.05572","0.12272"
"1.50000","0.05996","-0.06921"
"1.60000","0.06409","0.20170"
"1.70000","0.06830","0.02245"
"1.80000","0.07243","0.23257"
"1.90000","0.07658","0.03630"
"2.00000","0.08077","0.14154"
"2.10000","0.08490","0.36385"
"2.20000","0.08912","-0.14263"
"2.30000","0.09325","0.15011"
"2.40000","0.09745","-0.15905"
"2.50000","0.10159","-0.06046"
"2.60000","0.10578","0.05975"
"2.70000","0.10995","-0.04298"
"2.80000","0.11411","-0.18052"
"2.90000","0.11825","0.10750"
"3.00000","0.12240","0.11894"
"3.10000","0.12658","-0.03394"
"3.20000","0.13072","0.31964"
"3.30000","0.13494","0.24525"
"3.40000","0.13909","-0.00295"
"3.50000","0.14327","0.13641"
"3.60000","0.14744","-0.13669"
"3.70000","0.15160","0.08177"
"3.80000","0.15576","-0.08474"
"3.90000","0.15992","-0.06550"
"4.00000","0.16411","0.01084"
"4.10000","0.16822","0.21387"
"4.20000","0.17245","0.24061"
"4.30000","0.17658","-0.05341"
"4.40000","0.18081","0.01239"
"4.50000","0.18496","0.04627"
"4.60000","0.18909","0.28238"
"4.70000","0.19326","-0.20914"
"4.80000","0.19736","0.10070"
"4.90000","0.20158","0.08977"
"5.00000","0.20573","-0.00246"
"5.10000","0.20992","0.00474"
"5.20000","0.21409","0.21380"
"5.30000","0.21828","0.40065"
"5.40000","0.22242","0.04462"
"5.50000","0.22662","-0.05528"
"5.60000","0.23079","-0.14278"
"5.70000","0.23492","-0.18748"
"5.80000","0.23911","-0.09579"
"5.90000","0.24322","0.05080"
"6.00000","0.24743","0.02504"
"6.10000","0.25158","0.15820"
"6.20000","0.25579","0.30055"
"6.30000","0.25997","-0.01721"
"6.40000","0.26411","0.32757"
"6.50000","0.26830","0.03374"
"6.60000","0.27242","0.16764"
"6.70000","0.27659","-0.08382"
"6.80000","0.28073","0.07312"
"6.90000","0.28492","-0.00564"
"7.00000","0.28905","0.07141"
"7.10000","0.29325","-0.02438"
"7.20000","0.29742","0.18020"
"7.30000","0.30159","0.21079"
"7.40000","0.30581","0.33622"
"7.50000","0.30992","0.21792"
"7.60000","0.31411","-0.13199"
"7.70000","0.31823","0.05389"
"7.80000","0.32243","0.07867"
"7.90000","0.32659","0.11200"
"8.00000","0.33077","-0.06614"
"8.10000","0.33495","-0.10541"
"8.20000","0.33911","0.33411"
"8.30000","0.34328","0.17212"
"8.40000","0.34744","0.12957"
"8.50000","0.35164","-0.05153"
"8.60000","0.35574","0.03762"
"8.70000","0.35993","-0.14087"
"8.80000","0.36405","0.11971"
"8.90000","0.36824","0.36272"
"9.00000","0.37242","0.18331"
"9.10000","0.37659","0.05128"
"9.20000","0.38078","-0.00661"
"9.30000","0.38491","0.29403"
"9.40000","0.38910","0.15300"
"9.50000","0.39326","-0.01056"
"9.60000","0.39744","0.04529"
"9.70000","0.40160","0.28433"
"9.80000","0.40576","0.03617"
"9.90000","0.40993","0.35013"
"10.00000","0.41409","0.14750"
"10.10000","0.41831","0.00324"
"10.20000","0.42243","-0.16359"
"10.30000","0.42664","0.04852"
"10.40000","0.43077","0.20355"
"10.50000","0.43492","0.19780"
"10.60000","0.43910","0.25894"
"10.70000","0.44323","0.22624"
"10.80000","0.44743","0.09771"
"10.90000","0.45157","0.01758"
"11.00000","0.45576","0.21235"
"11.10000","0.45991","0.17128"
"11.20000","0.46411","-0.08436"
"11.30000","0.46826","0.42312"
"11.40000","0.47245","0.15552"
"11.50000","0.47659","0.15355"
"11.60000","0.48073","0.30451"
"11.70000","0.48493","0.14963"
"11.80000","0.48905","0.19142"
"11.90000","0.49330","0.42337"
"12.00000","0.49743","0.17743"
"12.10000","0.50163","-0.00184"
"12.20000","0.50579","0.20828"
"12.30000","0.50994","0.29785"
"12.40000","0.51411","0.02872"
"12.50000","0.51825","0.43247"
"12.60000","0.52242","0.16951"
"12.70000","0.52656","0.26640"
"12.80000","0.53075","0.03699"
"12.90000","0.53489","0.30830"
"13.00000","0.53913","0.30453"
"13.10000","0.54327","-0.11826"
"13.20000","0.54745","0.00946"
"13.30000","0.55161","0.29617"
"13.40000","0.55572","0.05897"
"13.50000","0.55994","0.30547"
"13.60000","0.56406","0.28533"
"13.70000","0.56828","0.32600"
"13.80000","0.57242","-0.28769"
"13.90000","0.57663","0.33523"
"14.00000","0.58078","0.03913"
"14.10000","0.58495","0.02075"
"14.20000","0.58914","-0.07880"
"14.30000","0.59324","0.13924"
"14.40000","0.59744","0.24027"
"14.50000","0.60154","0.55378"
"14.60000","0.60576","0.26356"
"14.70000","0.60989","0.19811"
"14.80000","0.61411","0.23477"
"14.90000","0.61828","0.27075"
"15.00000","0.62243","0.12112"
"15.10000","0.62662","-0.08945"
"15.20000","0.63074","0.11625"
"15.30000","0.63492","0.31762"
"15.40000","0.63906","0.19184"
"15.50000","0.64326","0.26078"
"15.60000","0.64739","0.08253"
"15.70000","0.65162","0.29842"
"15.80000","0.65578","0.15764"
"15.90000","0.65996","-0.19503"
"16.00000","0.66415","0.16016"
"16.10000","0.66825","-0.05751"
"16.20000","0.67246","0.11418"
"16.30000","0.67654","0.27500"
"16.40000","0.68076","0.31463"
"16.50000","0.68490","0.37429"
"16.60000","0.68908","0.31675"
"16.70000","0.69327","0.62644"
"16.80000","0.69742","0.27362"
"16.90000","0.70161","0.14154"
"17.00000","0.70574","0.25121"
"17.10000","0.70997","0.21048"
"17.20000","0.71407","0.33830"
"17.30000","0.71828","0.16343"
"17.40000","0.72239","0.08049"
"17.50000","0.72658","0.15942"
"17.60000","0.73077","0.23116"
"17.70000","0.73494","0.35588"
"17.80000","0.73915","0.17645"
"17.90000","0.74326","0.50173"
"18.00000","0.74746","0.40130"
"18.10000","0.75158","0.13624"
"18.20000","0.75578","0.33990"
"18.30000","0.75991","0.32938"
"18.40000","0.76409","0.30427"
"18.50000","0.76822","0.26779"
"18.60000","0.77239","0.23166"
"18.70000","0.77661","0.22241"
"18.80000","0.78074","0.57109"
"18.90000","0.78497","0.12730"
"19.00000","0.78907","0.00915"
"19.10000","0.79327","0.04351"
"19.20000","0.79742","0.45473"
"19.30000","0.80159","0.28896"
"19.40000","0.80576","0.22938"
"19.50000","0.80992","0.17950"
"19.60000","0.81411","0.19877"
"19.70000","0.81826","0.12255"
"19.80000","0.82244","0.23239"
"19.90000","0.82660","0.14081"
"20.00000","0.83081","0.13484"
"20.10000","0.83490","0.34199"
"20.20000","0.83910","0.71090"
"20.30000","0.84324","0.18549"
"20.40000","0.84739","0.24823"
"20.50000","0.85161","0.32723"
"20.60000","0.85574","0.10422"
"20.70000","0.85994","0.33328"
"20.80000","0.86409","0.17180"
"20.90000","0.86828","0.38458"
"21.00000","0.87243","0.38185"
"21.10000","0.87660","0.07720"
"21.20000","0.88076","0.09765"
"21.30000","0.88491","0.33663"
"21.40000","0.88910","0.20761"
"21.50000","0.89325","0.19281"
"21.60000","0.89748","0.38466"
"21.70000","0.90162","0.27961"
"21.80000","0.90579","0.19058"
"21.90000","0.90993","0.37962"
"22.00000","0.91407","0.35100"
"22.10000","0.91825","0.11823"
"22.20000","0.92239","0.20261"
"22.30000","0.92659","0.05101"
"22.40000","0.93073","0.14367"
"22.50000","0.93494","0.18298"
"22.60000","0.93909","0.24852"
"22.70000","0.94329","0.37325"
"22.80000","0.94745","0.15978"
"22.90000","0.95160","0.16770"
"23.00000","0.95576","0.44931"
"23.10000","0.95988","0.36508"
"23.20000","0.96409","0.08123"
"23.30000","0.96823","0.07395"
"23.40000","0.97246","0.15783"
"23.50000","0.97661","0.13657"
"23.60000","0.98078","0.28155"
"23.70000","0.98497","0.09623"
"23.80000","0.98909","0.21928"
"23.90000","0.99327","0.21496"
"24.00000","0.99741","0.23163"
"24.10000","1.00156","0.20049"
"24.20000","1.00572","0.39109"
"24.30000","1.00991","0.21186"
"24.40000","1.01407","0.21290"
"24.50000","1.01829","0.34782"
"24.60000","1.02246","0.29346"
"24.70000","1.02660","0.25612"
"24.80000","1.03078","-0.05946"
"24.90000","1.03490","0.22416"
"25.00000","1.03909","0.33222"
"25.10000","1.04325","0.23307"
"25.20000","1.04743","0.22009"
"25.30000","1.05161","0.35035"
"25.40000","1.05578","0.32806"
"25.50000","1.05994","0.22149"
"25.60000","1.06412","0.34926"
"25.70000","1.06829","0.49712"
"25.80000","1.07240","0.13124"
"25.90000","1.07659","0.40765"
"26.00000","1.08071","0.31111"
"26.10000","1.08491","0.46413"
"26.20000","1.08908","0.42384"
"26.30000","1.09326","0.32578"
"26.40000","1.09744","0.29803"
"26.50000","1.10158","0.41370"
"26.60000","1.10579","0.10683"
"26.70000","1.10993","0.16176"
"26.80000","1.11410","0.17950"
"26.90000","1.11827","0.31994"
"27.00000","1.12242","0.25141"
"27.10000","1.12658","0.22178"
"27.20000","1.13076","-0.01409"
"27.30000","1.13497","0.00983"
"27.40000","1.13912","0.15101"
"27.50000","1.14331","0.56778"
"27.60000","1.14742","0.03375"
"27.70000","1.15160","0.05635"
"27.80000","1.15574","0.46405"
"27.90000","1.15993","0.52686"
"28.00000","1.16409","0.06501"
"28.10000","1.16822","0.17678"
"28.20000","1.17243","0.23946"
"28.30000","1.17658","-0.06737"
"28.40000","1.18078","0.50031"
"28.50000","1.18492","0.05091"
"28.60000","1.18913","0.27213"
"28.70000","1.19324","0.15048"
"28.80000","1.19742","0.41826"
"28.90000","1.20158","0.46371"
"29.00000","1.20572","0.53252"
"29.10000","1.20995","0.29054"
"29.20000","1.21410","0.36835"
"29.30000","1.21830","0.28761"
"29.40000","1.22244","0.06507"
"29.50000","1.22661","0.12624"
"29.60000","1.23077","0.41081"
"29.70000","1.23493","0.66843"
"29.80000","1.23907","0.47237"
"29.90000","1.24323","0.20488"
"30.00000","1.24740","0.17355"
"30.10000","1.25156","0.35860"
"30.20000","1.25579","0.38612"
"30.30000","1.25992","0.06511"
"30.40000","1.26412","0.46757"
"30.50000","1.26826","0.42475"
"30.60000","1.27241","0.04910"
"30.70000","1.27660","0.47206"
"30.80000","1.28074","0.21824"
"30.90000","1.28495","0.37856"
"31.00000","1.28907","0.29869"
"31.10000","1.29328","0.40895"
"31.20000","1.29744","0.20575"
"31.30000","1.30162","0.16085"
"31.40000","1.30579","0.16440"
"31.50000","1.30995","-0.05959"
"31.60000","1.31409","0.47047"
"31.70000","1.31823","0.31125"
"31.80000","1.32242","0.13850"
"31.90000","1.32655","0.45611"
"32.00000","1.33078","0.31620"
"32.10000","1.33492","0.52844"
"32.20000","1.33910","0.15675"
"32.30000","1.34327","0.77317"
"32.40000","1.34744","0.44919"
"32.50000","1.35159","0.08919"
"32.60000","1.35575","0.56581"
"32.70000","1.35993","0.25592"
"32.80000","1.36406","0.61401"
"32.90000","1.36828","0.27331"
"33.00000","1.37243","0.34309"
"33.10000","1.37665","0.33203"
"33.20000","1.38081","0.53371"
"33.30000","1.38493","0.22698"
"33.40000","1.38911","0.34915"
"33.50000","1.39321","0.66321"
"33.60000","1.39743","-0.06784"
"33.70000","1.40156","0.15934"
"33.80000","1.40575","0.12145"
"33.90000","1.40991","0.44855"
"34.00000","1.41410","0.22321"
"34.10000","1.41827","0.21943"
"34.20000","1.42245","0.23574"
"34.30000","1.42663","0.44600"
"34.40000","1.43073","0.56940"
"34.50000","1.43492","0.25776"
"34.60000","1.43904","0.22719"
"34.70000","1.44326","0.39242"
"34.80000","1.44741","0.40319"
"34.90000","1.45163","0.26265"
"35.00000","1.45578","0.44391"
"35.10000","1.45995","0.11827"
"35.20000","1.46413","0.70235"
"35.30000","1.46826","0.24091"
"35.40000","1.47244","0.28660"
"35.50000","1.47658","0.33645"
"35.60000","1.48075","0.41560"
"35.70000","1.48490","0.42763"
"35.80000","1.48909","0.10163"
"35.90000","1.49326","0.20607"
"36.00000","1.49743","0.18865"
"36.10000","1.50161","0.15968"
"36.20000","1.50575","0.32850"
"36.30000","1.50994","0.21536"
"36.40000","1.51407","0.36237"
"36.50000","1.51825","0.42682"
"36.60000","1.52243","0.60248"
"36.70000","1.52658","0.38926"
"36.80000","1.53077","0.27728"
"36.90000","1.53494","0.42499"
"37.00000","1.53911","0.28499"
"37.10000","1.54327","0.29595"
"37.20000","1.54746","0.58257"
"37.30000","1.55155","0.35951"
"37.40000","1.55577","0.45699"
"37.50000","1.55990","0.15746"
"37.60000","1.56407","0.61346"
"37.70000","1.56827","0.62177"
"37.80000","1.57240","0.15680"
"37.90000","1.57660","0.14306"
"38.00000","1.58075","0.41502"
"38.10000","1.58495","0.59506"
"38.20000","1.58909","0.29046"
"38.30000","1.59327","0.30609"
"38.40000","1.59741","0.44634"
"38.50000","1.60160","0.32247"
"38.60000","1.60576","0.45321"
"38.70000","1.60993","0.32746"
"38.80000","1.61415","0.47395"
"38.90000","1.61827","0.51988"
"39.00000","1.62245","0.54318"
"39.10000","1.62659","0.26775"
"39.20000","1.63074","0.47106"
"39.30000","1.63492","0.38469"
"39.40000","1.63907","0.19677"
"39.50000","1.64326","0.60440"
"39.60000","1.64739","0.18693"
"39.70000","1.65161","0.20114"
"39.80000","1.65575","0.33510"
"39.90000","1.65996","0.43714"
"40.00000","1.66411","0.53427"
"40.10000","1.66829","0.40902"
"40.20000","1.67242","0.42055"
"40.30000","1.67656","0.42475"
"40.40000","1.68077","0.43717"
"40.50000","1.68488","0.40555"
"40.60000","1.68914","0.34760"
"40.70000","1.69327","0.40612"
"40.80000","1.69745","0.41645"
"40.90000","1.70162","0.33625"
"41.00000","1.70577","0.23722"
"41.10000","1.70994","0.29167"
"41.20000","1.71409","0.27490"
"41.30000","1.71823","0.27719"
"41.40000","1.72238","0.46610"
"41.50000","1.72658","0.27370"
"41.60000","1.73072","0.34065"
"41.70000","1.73496","0.18007"
"41.80000","1.73912","0.49883"
"41.90000","1.74328","0.14358"
"42.00000","1.74745","0.34025"
"42.10000","1.75156","0.20887"
"42.20000","1.75578","0.19325"
"42.30000","1.75990","0.37677"
"42.40000","1.76410","0.56104"
"42.50000","1.76825","0.59778"
"42.60000","1.77245","0.42799"
"42.70000","1.77662","0.66025"
"42.80000","1.78078","0.43337"
"42.90000","1.78496","0.30028"
"43.00000","1.78906","0.43132"
"43.10000","1.79327","0.44968"
"43.20000","1.79737","0.50299"
"43.30000","1.80159","0.24264"
"43.40000","1.80573","0.62230"
"43.50000","1.80993","0.31591"
"43.60000","1.81409","0.43809"
"43.70000","1.81825","0.36627"
"43.80000","1.82246","0.28911"
"43.90000","1.82660","0.35148"
"44.00000","1.83078","0.51865"
"44.10000","1.83490","0.48775"
"44.20000","1.83910","0.20282"
"44.30000","1.84323","0.19458"
"44.40000","1.84745","0.29752"
"44.50000","1.85161","0.30383"
"44.60000","1.85579","0.58335"
"44.70000","1.85999","0.63230"
"44.80000","1.86407","0.49348"
"44.90000","1.86829","0.60281"
"45.00000","1.87237","0.26448"
"45.10000","1.87660","0.40993"
"45.20000","1.88075","0.49571"
"45.30000","1.88490","0.58929"
"45.40000","1.88911","0.42083"
"45.50000","1.89324","0.55402"
"45.60000","1.89744","0.49795"
"45.70000","1.90159","0.17781"
"45.80000","1.90581","0.26796"
"45.90000","1.90989","0.64731"
"46.00000","1.91411","0.48465"
"46.10000","1.91824","0.40490"
"46.20000","1.92242","0.38654"
"46.30000","1.92661","0.54454"
"46.40000","1.93077","0.58316"
"46.50000","1.93497","0.47095"
"46.60000","1.93909","0.27620"
"46.70000","1.94329","0.28480"
"46.80000","1.94742","0.66795"
"46.90000","1.95161","0.40204"
"47.00000","1.95575","0.33030"
"47.10000","1.95993","0.75497"
"47.20000","1.96406","0.60868"
"47.30000","1.96823","0.41553"
"47.40000","1.97244","0.19933"
"47.50000","1.97657","0.74466"
"47.60000","1.98080","0.27603"
"47.70000","1.98491","0.47161"
"47.80000","1.98910","0.39699"
"47.90000","1.99325","0.25239"
"48.00000","1.99743","0.40966"
"48.10000","2.00161","0.80846"
"48.20000","2.00574","0.32133"
"48.30000","2.00995","0.52687"
"48.40000","2.01410","0.82033"
"48.50000","2.01828","0.70549"
"48.60000","2.02242","0.44326"
"48.70000","2.02664","0.31901"
"48.80000","2.03073","0.58242"
"48.90000","2.03492","0.40367"
"49.00000","2.03907","0.42724"
"49.10000","2.04323","0.40781"
"49.20000","2.04744","0.44461"
"49.30000","2.05157","0.46302"
"49.40000","2.05578","0.49330"
"49.50000","2.05992","0.52087"
"49.60000","2.06411","0.67403"
"49.70000","2.06826","0.81365"
"49.80000","2.07242","0.59321"
"49.90000","2.07659","0.33319"
"50.00000","2.08074","0.62836"
"50.10000","2.08493","0.72820"
"50.20000","2.08908","0.43765"
"50.30000","2.09332","0.25027"
"50.40000","2.09745","0.53067"
"50.50000","2.10162","0.60998"
"50.60000","2.10576","0.55974"
"50.70000","2.10990","0.51524"
"50.80000","2.11409","0.55537"
"50.90000","2.11823","0.38481"
"51.00000","2.12242","0.66324"
"51.10000","2.12656","0.66305"
"51.20000","2.13076","0.38700"
"51.30000","2.13492","0.30483"
"51.40000","2.13912","0.68112"
"51.50000","2.14329","0.68521"
"51.60000","2.14743","0.61468"
"51.70000","2.15158","0.17422"
"51.80000","2.15571","0.83891"
"51.90000","2.15992","0.61657"
"52.00000","2.16406","0.81820"
"52.10000","2.16830","0.80357"
"52.20000","2.17244","0.53158"
"52.30000","2.17661","0.22050"
"52.40000","2.18081","0.28109"
"52.50000","2.18495","0.68963"
"52.60000","2.18911","0.45999"
"52.70000","2.19324","0.46917"
"52.80000","2.19741","0.57415"
"52.90000","2.20155","0.58119"
"53.00000","2.20575","0.44186"
"53.10000","2.20992","0.34184"
"53.20000","2.21411","0.51119"
"53.30000","2.21828","0.56302"
"53.40000","2.22242","0.62510"
"53.50000","2.22661","0.56948"
"53.60000","2.23073","0.72394"
"53.70000","2.23493","0.66349"
"53.80000","2.23909","0.31785"
"53.90000","2.24326","0.58856"
"54.00000","2.24744","0.49627"
"54.10000","2.25161","0.43837"
"54.20000","2.25578","0.30461"
"54.30000","2.25995","0.52651"
"54.40000","2.26413","0.33792"
"54.50000","2.26824","0.54929"
"54.60000","2.27244","0.63926"
"54.70000","2.27656","0.31892"
"54.80000","2.28074","0.35963"
"54.90000","2.28492","0.45392"
"55.00000","2.28910","0.38907"
"55.10000","2.29327","0.63942"
"55.20000","2.29742","0.52551"
"55.30000","2.30162","0.63285"
"55.40000","2.30576","0.41530"
"55.50000","2.30993","0.69118"
"55.60000","2.31409","0.53686"
"55.70000","2.31826","0.38614"
"55.80000","2.32241","0.55761"
"55.90000","2.32660","0.78524"
"56.00000","2.33079","0.73655"
"56.10000","2.33493","0.55096"
"56.20000","2.33914","0.24451"
"56.30000","2.34325","0.45506"
"56.40000","2.34744","0.66975"
"56.50000","2.35157","0.52805"
"56.60000","2.35575","0.71338"
"56.70000","2.35993","0.39414"
"56.80000","2.36406","0.58954"
"56.90000","2.36828","0.55474"
"57.00000","2.37241","0.86130"
"57.10000","2.37661","0.83762"
"57.20000","2.38076","0.47012"
"57.30000","2.38496","0.16755"
"57.40000","2.38909","0.49162"
"57.50000","2.39325","0.57981"
"57.60000","2.39741","0.46170"
"57.70000","2.40156","0.67984"
"57.80000","2.40579","0.52547"
"57.90000","2.40992","0.46604"
"58.00000","2.41414","0.55523"
"58.10000","2.41827","0.44014"
"58.20000","2.42245","0.50709"
"58.30000","2.42659","0.67350"
"58.40000","2.43076","0.35074"
"58.50000","2.43491","0.54423"
"58.60000","2.43908","0.35074"
"58.70000","2.44323","0.86503"
"58.80000","2.44738","0.63252"
"58.90000","2.45161","0.58761"
"59.00000","2.45576","0.72794"
"59.10000","2.45997","0.51041"
"59.20000","2.46410","0.87552"
"59.30000","2.46824","0.61785"
"59.40000","2.47244","0.59635"
"59.50000","2.47656","0.54659"
"59.60000","2.48077","0.68404"
"59.70000","2.48490","0.52187"
"59.80000","2.48912","0.70162"
"59.90000","2.49327","0.67322"
"60.00000","2.49745","0.67129"
"60.10000","2.50162","0.53593"
"60.20000","2.50577","0.82827"
"60.30000","2.50993","0.81119"
"60.40000","2.51406","0.99616"
"60.50000","2.51824","0.51187"
"60.60000","2.52237","0.96908"
"60.70000","2.52660","0.88625"
"60.80000","2.53076","0.76043"
"60.90000","2.53494","1.06592"
"61.00000","2.53912","0.91625"
"61.10000","2.54328","0.98360"
"61.20000","2.54743","1.45067"
"61.30000","2.55158","1.47228"
"61.40000","2.55576","1.89045"
"61.50000","2.55989","1.99943"
"61.60000","2.56411","2.08119"
"61.70000","2.56826","2.80068"
"61.80000","2.57248","2.88679"
"61.90000","2.57664","3.32971"
"62.00000","2.58077","3.45772"
"62.10000","2.58494","3.69090"
"62.20000","2.58905","4.02937"
"62.30000","2.59326","3.98277"
"62.40000","2.59739","4.65496"
"62.50000","2.60158","4.93101"
"62.60000","2.60575","5.39618"
"62.70000","2.60993","5.33378"
"62.80000","2.61409","5.98739"
"62.90000","2.61828","5.95211"
"63.00000","2.62246","6.30339"
"63.10000","2.62658","6.34109"
"63.20000","2.63078","6.36727"
"63.30000","2.63488","6.68117"
"63.40000","2.63910","7.07704"
"63.50000","2.64325","7.33539"
"63.60000","2.64745","7.51664"
"63.70000","2.65162","7.17935"
"63.80000","2.65577","5.83262"
"63.90000","2.65997","5.17312"
"64.00000","2.66409","5.38792"
"64.10000","2.66827","5.15487"
"64.20000","2.67241","5.19227"
"64.30000","2.67657","4.88227"
"64.40000","2.68071","4.78882"
"64.50000","2.68492","5.06429"
"64.60000","2.68909","5.01592"
"64.70000","2.69326","4.89413"
"64.80000","2.69746","4.95174"
"64.90000","2.70157","4.98754"
"65.00000","2.70577","5.31474"
"65.10000","2.70990","4.87414"
"65.20000","2.71409","5.26731"
"65.30000","2.71827","5.09087"
"65.40000","2.72243","5.36605"
"65.50000","2.72662","5.65937"
"65.60000","2.73077","5.47870"
"65.70000","2.73494","5.43099"
"65.80000","2.73911","5.60464"
"65.90000","2.74330","5.31425"
"66.00000","2.74740","5.58400"
"66.10000","2.75159","5.54595"
"66.20000","2.75573","5.96621"
"66.30000","2.75990","6.30420"
"66.40000","2.76410","6.30373"
"66.50000","2.76824","6.95444"
"66.60000","2.77244","7.09101"
"66.70000","2.77658","7.31344"
"66.80000","2.78077","7.71622"
"66.90000","2.78492","8.02016"
"67.00000","2.78909","8.69393"
"67.10000","2.79325","8.71673"
"67.20000","2.79742","8.58790"
"67.30000","2.80159","9.06081"
"67.40000","2.80576","9.37863"
"67.50000","2.80998","9.61543"
"67.60000","2.81411","10.10685"
"67.70000","2.81830","9.83543"
"67.80000","2.82241","10.12275"
"67.90000","2.82659","10.48650"
"68.00000","2.83074","10.54010"
"68.10000","2.83491","10.55862"
"68.20000","2.83909","11.23059"
"68.30000","2.84323","11.34862"
"68.40000","2.84744","11.54713"
"68.50000","2.85159","11.49556"
"68.60000","2.85580","11.69341"
"68.70000","2.85994","11.09248"
"68.80000","2.86412","10.56181"
"68.90000","2.86826","10.43663"
"69.00000","2.87239","10.23165"
"69.10000","2.87660","10.17914"
"69.20000","2.88071","10.03373"
"69.30000","2.88497","10.19349"
"69.40000","2.88909","10.46452"
"69.50000","2.89330","11.01119"
"69.60000","2.89746","11.79544"
"69.70000","2.90161","11.95799"
"69.80000","2.90578","12.94153"
"69.90000","2.90992","13.34461"
"70.00000","2.91408","13.77527"
"70.10000","2.91822","14.21918"
"70.20000","2.92241","14.40925"
"70.30000","2.92655","15.01328"
"70.40000","2.93079","15.54592"
"70.50000","2.93495","15.95199"
"70.60000","2.93912","16.41412"
"70.70000","2.94327","16.61278"
"70.80000","2.94739","17.09712"
"70.90000","2.95161","17.48174"
"71.00000","2.95572","18.31946"
"71.10000","2.95993","18.60995"
"71.20000","2.96408","18.75044"
"71.30000","2.96829","19.16529"
"71.40000","2.97244","19.87012"
"71.50000","2.97660","20.05795"
"71.60000","2.98080","20.59685"
"71.70000","2.98493","20.99829"
"71.80000","2.98911","21.53207"
"71.90000","2.99321","22.05367"
"72.00000","2.99743","22.35506"
"72.10000","3.00156","23.03512"
"72.20000","3.00576","23.09661"
"72.30000","3.00994","23.61440"
"72.40000","3.01408","23.95795"
"72.50000","3.01829","24.71859"
"72.60000","3.02241","24.82243"
"72.70000","3.02660","25.27522"
"72.80000","3.03074","25.62794"
"72.90000","3.03494","25.52848"
"73.00000","3.03908","25.36026"
"73.10000","3.04328","25.63935"
"73.20000","3.04744","25.14457"
"73.30000","3.05161","24.54764"
"73.40000","3.05581","24.46408"
"73.50000","3.05990","24.53325"
"73.60000","3.06413","24.92594"
"73.70000","3.06821","25.21596"
"73.80000","3.07243","25.39197"
"73.90000","3.07657","25.60360"
"74.00000","3.08076","26.16187"
"74.10000","3.08494","26.86456"
"74.20000","3.08908","27.17432"
"74.30000","3.09328","28.07765"
"74.40000","3.09741","28.68107"
"74.50000","3.10163","29.30829"
"74.60000","3.10574","29.84662"
"74.70000","3.10994","30.59545"
"74.80000","3.11406","30.99590"
"74.90000","3.11825","31.94063"
"75.00000","3.12245","32.28393"
"75.10000","3.12660","33.34845"
"75.20000","3.13081","33.63602"
"75.30000","3.13492","34.71121"
"75.40000","3.13913","35.33657"
"75.50000","3.14325","36.24365"
"75.60000","3.14743","36.85382"
"75.70000","3.15158","37.53065"
"75.80000","3.15575","38.43836"
"75.90000","3.15991","39.11071"
"76.00000","3.16406","39.96109"
"76.10000","3.16828","40.68462"
"76.20000","3.17241","41.38662"
"76.30000","3.17665","42.27220"
"76.40000","3.18074","42.97121"
"76.50000","3.18494","43.64300"
"76.60000","3.18908","44.17473"
"76.70000","3.19324","45.17186"
"76.80000","3.19744","46.05539"
"76.90000","3.20159","46.59614"
"77.00000","3.20578","47.91552"
"77.10000","3.20993","48.56128"
"77.20000","3.21411","49.14614"
"77.30000","3.21827","50.25970"
"77.40000","3.22247","50.76649"
"77.50000","3.22657","51.90609"
"77.60000","3.23075","52.77453"
"77.70000","3.23490","53.67822"
"77.80000","3.23905","54.37036"
"77.90000","3.24327","55.44987"
"78.00000","3.24742","56.52273"
"78.10000","3.25161","57.33648"
"78.20000","3.25576","58.52374"
"78.30000","3.25995","59.32021"
"78.40000","3.26409","60.55269"
"78.50000","3.26826","61.49424"
"78.60000","3.27242","62.04895"
"78.70000","3.27657","63.48036"
"78.80000","3.28077","64.80067"
"78.90000","3.28491","66.03019"
"79.00000","3.28914","66.81342"
"79.10000","3.29328","67.99583"
"79.20000","3.29746","69.20981"
"79.30000","3.30161","70.47048"
"79.40000","3.30573","71.81187"
"79.50000","3.30993","72.97873"
"79.60000","3.31406","74.10196"
"79.70000","3.31825","75.53633"
"79.80000","3.32240","76.34174"
"79.90000","3.32660","77.78235"
"80.00000","3.33076","79.00325"
"80.10000","3.33496","80.01179"
"80.20000","3.33912","81.33861"
"80.30000","3.34328","82.67765"
"80.40000","3.34743","83.98881"
"80.50000","3.35155","84.77695"
"80.60000","3.35577","86.40601"
"80.70000","3.35990","87.63562"
"80.80000","3.36414","88.83699"
"80.90000","3.36828","90.37461"
"81.00000","3.37245","91.51697"
"81.10000","3.37663","92.76741"
"81.20000","3.38076","93.96882"
"81.30000","3.38494","95.12719"
"81.40000","3.38908","96.14378"
"81.50000","3.39325","97.47643"
"81.60000","3.39739","98.49213"
"81.70000","3.40158","100.12920"
"81.80000","3.40573","100.94003"
"81.90000","3.40995","102.33138"
"82.00000","3.41412","103.52978"
"82.10000","3.41825","104.57950"
"82.20000","3.42246","105.61792"
"82.30000","3.42656","106.55835"
"82.40000","3.43077","107.69456"
"82.50000","3.43491","109.26621"
"82.60000","3.43909","110.02529"
"82.70000","3.44328","111.24104"
"82.80000","3.44745","112.16383"
"82.90000","3.45161","113.07426"
"83.00000","3.45577","114.24778"
"83.10000","3.45996","115.51941"
"83.20000","3.46406","116.26935"
"83.30000","3.46826","117.59209"
"83.40000","3.47239","118.68890"
"83.50000","3.47658","119.39742"
"83.60000","3.48075","120.52232"
"83.70000","3.48493","121.62352"
"83.80000","3.48911","122.27106"
"83.90000","3.49324","123.35554"
"84.00000","3.49744","124.53542"
"84.10000","3.50159","125.59768"
"84.20000","3.50576","126.32096"
"84.30000","3.50992","127.40993"
"84.40000","3.51410","128.48259"
"84.50000","3.51825","129.44559"
"84.60000","3.52244","130.65248"
"84.70000","3.52664","131.18723"
"84.80000","3.53077","132.53891"
"84.90000","3.53497","133.44017"
"85.00000","3.53908","134.42802"
"85.10000","3.54327","135.14665"
"85.20000","3.54740","136.15234"
"85.30000","3.55159","137.09605"
"85.40000","3.55575","138.06161"
"85.50000","3.55989","138.63657"
"85.60000","3.56409","139.76801"
"85.70000","3.56824","140.60698"
"85.80000","3.57244","141.05345"
"85.90000","3.57659","142.02614"
"86.00000","3.58080","142.70699"
"86.10000","3.58492","143.70984"
"86.20000","3.58909","144.70000"
"86.30000","3.59325","145.21773"
"86.40000","3.59739","146.37291"
"86.50000","3.60163","146.59364"
"86.60000","3.60576","147.30048"
"86.70000","3.60997","148.15707"
"86.80000","3.61410","148.87381"
"86.90000","3.61829","149.72960"
"87.00000","3.62244","150.39429"
"87.10000","3.62659","150.86151"
"87.20000","3.63075","151.83943"
"87.30000","3.63489","152.14293"
"87.40000","3.63908","152.96002"
"87.50000","3.64322","153.34558"
"87.60000","3.64746","154.29944"
"87.70000","3.65158","154.47017"
"87.80000","3.65580","155.41376"
"87.90000","3.65993","155.87291"
"88.00000","3.66408","156.66510"
"88.10000","3.66827","156.91661"
"88.20000","3.67239","157.78014"
"88.30000","3.67660","158.20631"
"88.40000","3.68075","158.63391"
"88.50000","3.68494","159.37227"
"88.60000","3.68909","159.87366"
"88.70000","3.69329","160.67754"
"88.80000","3.69745","161.22412"
"88.90000","3.70162","161.52167"
"89.00000","3.70576","162.37086"
"89.10000","3.70989","163.01219"
"89.20000","3.71408","163.50569"
"89.30000","3.71822","163.99246"
"89.40000","3.72243","164.86224"
"89.50000","3.72659","165.23070"
"89.60000","3.73077","166.03833"
"89.70000","3.73495","166.07500"
"89.80000","3.73910","167.07289"
"89.90000","3.74326","167.69621"
"90.00000","3.74742","168.34932"
"90.10000","3.75158","168.93866"
"90.20000","3.75573","169.57036"
"90.30000","3.75993","170.41692"
"90.40000","3.76409","170.80699"
"90.50000","3.76830","171.59727"
"90.60000","3.77247","172.31999"
"90.70000","3.77659","172.88586"
"90.80000","3.78079","173.62042"
"90.90000","3.78489","173.98924"
"91.00000","3.78910","174.78091"
"91.10000","3.79323","175.80139"
"91.20000","3.79743","176.07497"
"91.30000","3.80158","176.58368"
"91.40000","3.80578","177.77473"
"91.50000","3.80993","178.09430"
"91.60000","3.81411","178.85822"
"91.70000","3.81828","179.50975"
"91.80000","3.82241","180.02425"
"91.90000","3.82661","180.70790"
"92.00000","3.83072","181.40974"
"92.10000","3.83493","181.97630"
"92.20000","3.83908","182.89311"
"92.30000","3.84329","183.46896"
"92.40000","3.84745","184.44312"
"92.50000","3.85159","184.83461"
"92.60000","3.85580","185.71489"
"92.70000","3.85992","186.19315"
"92.80000","3.86409","187.22690"
"92.90000","3.86823","187.62904"
"93.00000","3.87242","188.27994"
"93.10000","3.87656","189.34663"
"93.20000","3.88075","189.81554"
"93.30000","3.88492","190.81435"
"93.40000","3.88909","191.73210"
"93.50000","3.89331","192.23257"
"93.60000","3.89741","192.77588"
"93.70000","3.90162","193.74471"
"93.80000","3.90573","194.36781"
"93.90000","3.90992","195.33655"
"94.00000","3.91408","196.03098"
"94.10000","3.91825","196.85805"
"94.20000","3.92244","197.68785"
"94.30000","3.92662","198.74522"
"94.40000","3.93078","199.39540"
"94.50000","3.93493","200.27049"
"94.60000","3.93913","200.86519"
"94.70000","3.94323","201.69218"
"94.80000","3.94742","202.56732"
"94.90000","3.95156","203.47725"
"95.00000","3.95573","204.23782"
"95.10000","3.95993","205.11723"
"95.20000","3.96408","205.80038"
"95.30000","3.96828","206.99998"
"95.40000","3.97241","207.58827"
"95.50000","3.97661","208.37502"
"95.60000","3.98076","209.41145"
"95.70000","3.98492","210.03859"
"95.80000","3.98909","210.88145"
"95.90000","3.99325","211.60625"
"96.00000","3.99742","212.79736"
"96.10000","4.00158","213.35872"
"96.20000","4.00581","214.27557"
"96.30000","4.00994","215.27313"
"96.40000","4.01414","216.12482"
"96.50000","4.01826","217.17822"
"96.60000","4.02242","218.15271"
"96.70000","4.02659","219.13567"
"96.80000","4.03073","219.52510"
"96.90000","4.03492","220.65414"
"97.00000","4.03907","221.45854"
"97.10000","4.04327","222.54951"
"97.20000","4.04741","223.07805"
"97.30000","4.05163","224.42157"
"97.40000","4.05576","225.23184"
"97.50000","4.05996","226.36943"
"97.60000","4.06410","227.15874"
"97.70000","4.06822","227.94861"
"97.80000","4.07243","228.83772"
"97.90000","4.07655","229.68140"
"98.00000","4.08080","230.93875"
"98.10000","4.08493","231.59145"
"98.20000","4.08913","232.88606"
"98.30000","4.09329","233.63045"
"98.40000","4.09744","234.52191"
"98.50000","4.10161","235.35841"
"98.60000","4.10575","236.42836"
"98.70000","4.10991","237.47772"
"98.80000","4.11405","238.25464"
"98.90000","4.11825","239.73207"
"99.00000","4.12239","240.42366"
"99.10000","4.12662","241.40056"
"99.20000","4.13078","242.62749"
"99.30000","4.13495","243.62852"
"99.40000","4.13913","244.54382"
"99.50000","4.14322","245.16862"
"99.60000","4.14745","246.50638"
"99.70000","4.15157","247.38402"
"99.80000","4.15578","248.62386"
"99.90000","4.15993","249.03514"
"100.00000","4.16411","250.47531"
"100.10000","4.16828","251.57832"
"100.20000","4.17244","252.35562"
"100.30000","4.17663","253.26878"
"100.40000","4.18073","254.50200"
"100.50000","4.18493","255.32468"
"100.60000","4.18904","256.42181"
"100.70000","4.19325","257.75562"
"100.80000","4.19740","258.25314"
"100.90000","4.20160","259.90417"
"101.00000","4.20578","260.52509"
"101.10000","4.20991","261.73239"
"101.20000","4.21412","262.80521"
"101.30000","4.21825","263.75037"
"101.40000","4.22243","265.14520"
"101.50000","4.22657","265.84842"
"101.60000","4.23077","267.08746"
"101.70000","4.23491","268.03665"
"101.80000","4.23911","269.32230"
"101.90000","4.24329","270.18362"
"102.00000","4.24745","271.09134"
"102.10000","4.25164","272.21790"
"102.20000","4.25573","273.31091"
"102.30000","4.25996","274.36148"
"102.40000","4.26405","275.43237"
"102.50000","4.26827","276.82303"
"102.60000","4.27241","277.47910"
"102.70000","4.27658","278.58572"
"102.80000","4.28078","279.92529"
"102.90000","4.28491","280.98682"
"103.00000","4.28912","282.26352"
"103.10000","4.29325","283.17554"
"103.20000","4.29748","284.07684"
"103.30000","4.30156","285.26917"
"103.40000","4.30578","286.52216"
"103.50000","4.30990","287.53137"
"103.60000","4.31407","288.49567"
"103.70000","4.31829","289.55103"
"103.80000","4.32244","290.82275"
"103.90000","4.32665","292.04095"
"104.00000","4.33076","292.83109"
"104.10000","4.33497","293.98660"
"104.20000","4.33909","294.91507"
"104.30000","4.34327","296.04605"
"104.40000","4.34741","296.96872"
"104.50000","4.35158","298.18149"
"104.60000","4.35572","299.38364"
"104.70000","4.35989","300.47620"
"104.80000","4.36412","301.54987"
"104.90000","4.36824","302.75070"
"105.00000","4.37247","303.95520"
"105.10000","4.37657","304.77011"
"105.20000","4.38076","305.90503"
"105.30000","4.38491","307.19189"
"105.40000","4.38908","307.91663"
"105.50000","4.39328","309.38354"
"105.60000","4.39741","310.49292"
"105.70000","4.40162","311.69907"
"105.80000","4.40577","312.87866"
"105.90000","4.40996","313.70184"
"106.00000","4.41411","315.14011"
"106.10000","4.41830","316.03696"
"106.20000","4.42242","317.25537"
"106.30000","4.42658","318.52686"
"106.40000","4.43073","319.32108"
"106.50000","4.43488","320.68433"
"106.60000","4.43911","321.70456"
"106.70000","4.44323","322.85510"
"106.80000","4.44744","323.89154"
"106.90000","4.45159","324.96307"
"107.00000","4.45578","326.11771"
"107.10000","4.45991","327.58432"
"107.20000","4.46411","328.59131"
"107.30000","4.46825","329.30109"
"107.40000","4.47239","330.88516"
"107.50000","4.47660","332.02405"
"107.60000","4.48074","332.90314"
"107.70000","4.48499","334.23230"
"107.80000","4.48912","334.92188"
"107.90000","4.49329","336.55780"
"108.00000","4.49744","337.63913"
"108.10000","4.50157","338.82635"
"108.20000","4.50577","340.04364"
"108.30000","4.50990","341.41873"
"108.40000","4.51408","342.34323"
"108.50000","4.51823","343.44257"
"108.60000","4.52244","344.86771"
"108.70000","4.52659","345.75494"
"108.80000","4.53079","347.18765"
"108.90000","4.53495","348.30573"
"109.00000","4.53909","349.07230"
"109.10000","4.54327","350.37646"
"109.20000","4.54738","351.26447"
"109.30000","4.55160","352.56516"
"109.40000","4.55573","353.84961"
"109.50000","4.55997","354.83380"
"109.60000","4.56410","356.19702"
"109.70000","4.56828","357.30798"
"109.80000","4.57246","358.47424"
"109.90000","4.57659","359.60321"
"110.00000","4.58077","360.74216"
"110.10000","4.58491","361.70251"
"110.20000","4.58908","362.84381"
"110.30000","4.59323","363.54135"
"110.40000","4.59743","365.03458"
"110.50000","4.60158","366.11935"
"110.60000","4.60578","367.35684"
"110.70000","4.60996","368.40378"
"110.80000","4.61409","369.21304"
"110.90000","4.61829","370.43106"
"111.00000","4.62239","371.41888"
"111.10000","4.62660","372.65878"
"111.20000","4.63075","374.14279"
"111.30000","4.63492","375.15292"
"111.40000","4.63910","375.76672"
"111.50000","4.64328","377.20273"
"111.60000","4.64745","377.74396"
"111.70000","4.65160","378.92279"
"111.80000","4.65579","380.09622"
"111.90000","4.65989","381.18869"
"112.00000","4.66410","382.49091"
"112.10000","4.66821","383.05371"
"112.20000","4.67241","384.13293"
"112.30000","4.67659","385.19217"
"112.40000","4.68076","386.03732"
"112.50000","4.68495","387.38354"
"112.60000","4.68908","387.92123"
"112.70000","4.69328","389.08356"
"112.80000","4.69742","389.82770"
"112.90000","4.70159","391.00278"
"113.00000","4.70575","391.85052"
"113.10000","4.70993","392.90646"
"113.20000","4.71408","393.81195"
"113.30000","4.71828","394.70145"
"113.40000","4.72247","395.61722"
"113.50000","4.72661","396.68021"
"113.60000","4.73079","397.64389"
"113.70000","4.73492","398.31137"
"113.80000","4.73910","399.03802"
"113.90000","4.74324","399.97391"
"114.00000","4.74742","400.37482"
"114.10000","4.75160","401.85342"
"114.20000","4.75572","402.61075"
"114.30000","4.75994","403.63107"
"114.40000","4.76408","404.25412"
"114.50000","4.76828","405.42755"
"114.60000","4.77244","406.05057"
"114.70000","4.77664","406.93240"
"114.80000","4.78074","407.56937"
"114.90000","4.78492","408.24466"
"115.00000","4.78908","409.10809"
"115.10000","4.79323","409.81485"
"115.20000","4.79746","410.70355"
"115.30000","4.80159","411.44669"
"115.40000","4.80580","412.07645"
"115.50000","4.80994","412.92459"
"115.60000","4.81411","413.58353"
"115.70000","4.81827","414.42996"
"115.80000","4.82244","414.79688"
"115.90000","4.82658","415.61578"
"116.00000","4.83073","416.26181"
"116.10000","4.83489","416.68378"
"116.20000","4.83905","417.75208"
"116.30000","4.84328","418.10220"
"116.40000","4.84742","418.72189"
"116.50000","4.85163","419.39978"
"116.60000","4.85577","419.86469"
"116.70000","4.85992","420.55627"
"116.80000","4.86411","420.91452"
"116.90000","4.86824","421.92996"
"117.00000","4.87244","422.49973"
"117.10000","4.87658","422.73468"
"117.20000","4.88078","423.48026"
"117.30000","4.88494","423.74756"
"117.40000","4.88912","424.42203"
"117.50000","4.89329","424.72037"
"117.60000","4.89745","425.24948"
"117.70000","4.90159","425.62497"
"117.80000","4.90572","426.39600"
"117.90000","4.90991","426.53601"
"118.00000","4.91405","426.92773"
"118.10000","4.91828","427.51160"
"118.20000","4.92242","427.90921"
"118.30000","4.92659","428.13953"
"118.40000","4.93076","428.81012"
"118.50000","4.93493","429.03732"
"118.60000","4.93910","429.52744"
"118.70000","4.94325","429.84119"
"118.80000","4.94742","429.85535"
"118.90000","4.95157","430.79550"
"119.00000","4.95578","430.97626"
"119.10000","4.95992","431.19653"
"119.20000","4.96414","431.58408"
"119.30000","4.96830","431.83820"
"119.40000","4.97244","432.00360"
"119.50000","4.97661","432.41342"
"119.60000","4.98072","432.66772"
"119.70000","4.98492","433.08206"
"119.80000","4.98907","433.12961"
"119.90000","4.99324","433.47650"
"120.00000","4.99742","433.32431"
"120.10000","5.00160","433.38388"
"120.20000","5.00577","433.84201"
"120.30000","5.00993","433.82706"
"120.40000","5.01413","434.30768"
"120.50000","5.01824","434.42599"
"120.60000","5.02243","434.43649"
"120.70000","5.02655","434.44000"
"120.80000","5.03076","435.01700"
"120.90000","5.03493","435.05389"
"121.00000","5.03912","434.97528"
"121.10000","5.04330","434.99579"
"121.20000","5.04745","435.25101"
"121.30000","5.05164","435.11133"
"121.40000","5.05576","434.95999"
"121.50000","5.05993","434.95023"
"121.60000","5.06407","435.13184"
"121.70000","5.06825","434.90976"
"121.80000","5.07239","435.29825"
"121.90000","5.07659","435.27075"
"122.00000","5.08076","435.30783"
"122.10000","5.08494","435.15506"
"122.20000","5.08913","435.28308"
"122.30000","5.09324","434.83414"
"122.40000","5.09744","435.03021"
"122.50000","5.10156","435.08853"
"122.60000","5.10575","435.05640"
"122.70000","5.10992","434.82101"
"122.80000","5.11409","434.67194"
"122.90000","5.11827","434.73923"
"123.00000","5.12245","434.69586"
"123.10000","5.12662","434.49240"
"123.20000","5.13076","434.47305"
"123.30000","5.13497","434.31274"
"123.40000","5.13906","434.14172"
"123.50000","5.14326","434.00146"
"123.60000","5.14739","433.79547"
"123.70000","5.15156","433.66965"
"123.80000","5.15575","433.52252"
"123.90000","5.15989","433.41479"
"124.00000","5.16411","433.28876"
"124.10000","5.16825","433.13297"
"124.20000","5.17244","432.75955"
"124.30000","5.17659","432.51590"
"124.40000","5.18076","432.08511"
"124.50000","5.18491","432.21140"
"124.60000","5.18909","432.02435"
"124.70000","5.19326","431.80234"
"124.80000","5.19741","431.41376"
"124.90000","5.20164","431.34244"
"125.00000","5.20577","431.08618"
"125.10000","5.20997","431.03799"
"125.20000","5.21410","430.51590"
"125.30000","5.21826","430.14017"
"125.40000","5.22243","429.91867"
"125.50000","5.22657","429.43793"
"125.60000","5.23076","429.38318"
"125.70000","5.23489","429.09155"
"125.80000","5.23910","428.81586"
"125.90000","5.24325","428.53452"
"126.00000","5.24746","428.28699"
"126.10000","5.25161","427.73904"
"126.20000","5.25579","427.48621"
"126.30000","5.25993","427.22519"
"126.40000","5.26406","426.92148"
"126.50000","5.26827","426.55960"
"126.60000","5.27238","426.23892"
"126.70000","5.27664","426.15955"
"126.80000","5.28076","425.81528"
"126.90000","5.28496","425.29562"
"127.00000","5.28913","425.02109"
"127.10000","5.29327","424.60257"
"127.20000","5.29743","424.35214"
"127.30000","5.30158","423.77927"
"127.40000","5.30575","423.33444"
"127.50000","5.30989","422.94803"
"127.60000","5.31408","422.47626"
"127.70000","5.31822","422.32196"
"127.80000","5.32246","421.83356"
"127.90000","5.32662","421.48837"
"128.00000","5.33078","421.41614"
"128.10000","5.33496","421.08066"
"128.20000","5.33907","420.33124"
"128.30000","5.34327","420.08435"
"128.40000","5.34739","419.53006"
"128.50000","5.35160","419.02295"
"128.60000","5.35575","418.83875"
"128.70000","5.35995","418.29648"
"128.80000","5.36410","417.95685"
"128.90000","5.36828","417.61551"
"129.00000","5.37246","417.25586"
"129.10000","5.37658","416.59711"
"129.20000","5.38077","416.45282"
"129.30000","5.38488","415.85446"
"129.40000","5.38908","415.65125"
"129.50000","5.39324","414.88821"
"129.60000","5.39744","414.61060"
"129.70000","5.40162","414.09888"
"129.80000","5.40575","413.76871"
"129.90000","5.40996","413.70221"
"130.00000","5.41409","413.04803"
"130.10000","5.41826","412.51987"
"130.20000","5.42241","412.16248"
"130.30000","5.42660","411.77942"
"130.40000","5.43073","411.21277"
"130.50000","5.43494","410.82611"
"130.60000","5.43912","410.29391"
"130.70000","5.44328","410.16205"
"130.80000","5.44749","409.44162"
"130.90000","5.45157","409.06091"
"131.00000","5.45578","408.67429"
"131.10000","5.45988","408.12000"
"131.20000","5.46409","407.82932"
"131.30000","5.46823","407.12283"
"131.40000","5.47242","406.88187"
"131.50000","5.47661","406.44684"
"131.60000","5.48076","406.04883"
"131.70000","5.48495","406.03714"
"131.80000","5.48909","404.98352"
"131.90000","5.49331","404.63809"
"132.00000","5.49740","404.00684"
"132.10000","5.50161","403.57355"
"132.20000","5.50573","403.51785"
"132.30000","5.50990","403.10922"
"132.40000","5.51411","402.72119"
"132.50000","5.51826","402.33679"
"132.60000","5.52248","401.97272"
"132.70000","5.52659","401.09128"
"132.80000","5.53080","401.01675"
"132.90000","5.53492","400.52551"
"133.00000","5.53911","399.82251"
"133.10000","5.54325","399.82037"
"133.20000","5.54742","399.15338"
"133.30000","5.55156","398.44955"
"133.40000","5.55572","397.95612"
"133.50000","5.55995","397.94946"
"133.60000","5.56408","397.44189"
"133.70000","5.56833","397.22653"
"133.80000","5.57241","396.64395"
"133.90000","5.57661","396.33569"
"134.00000","5.58075","395.91940"
"134.10000","5.58491","395.45139"
"134.20000","5.58911","394.74609"
"134.30000","5.59324","394.43243"
"134.40000","5.59745","394.14453"
"134.50000","5.60159","393.82986"
"134.60000","5.60579","393.49930"
"134.70000","5.60993","392.97269"
"134.80000","5.61413","392.77701"
"134.90000","5.61824","391.91028"
"135.00000","5.62242","391.95932"
"135.10000","5.62657","391.53494"
"135.20000","5.63071","390.77551"
"135.30000","5.63494","390.47168"
"135.40000","5.63908","390.11594"
"135.50000","5.64328","389.85831"
"135.60000","5.64742","389.63113"
"135.70000","5.65161","388.91913"
"135.80000","5.65575","388.61594"
"135.90000","5.65992","388.27588"
"136.00000","5.66410","387.88980"
"136.08900","5.66778","387.59366"